Workbook

Sheet Mode d'emploi
B1: Outil de suivi des entretiens de parcours professionnel (EPP)
B2: Article L6315-1 du Code du travail, dans sa rédaction issue de la loi n° 2025-989 du 24 octobre 2025 (JO du 25/10/2025), applicable depuis le 26 octobre 2025.
B4: 1. MODE D'EMPLOI
B5: ① Paramètres – Renseignez l'effectif de l'entreprise et complétez la liste des services. Vérifiez les délais : ils reprennent le Code du travail et peuvent être adaptés si un accord d'entreprise ou de branche prévoit des règles plus favorables.
B6: ② Suivi EPP – Une ligne par salarié ; saisissez uniquement dans les colonnes jaunes. Pour tout salarié ayant plus d'un an d'ancienneté, renseignez la date du précédent entretien professionnel (colonne L : ancien entretien biennal ou EPP) : c'est elle qui fait courir le délai de 4 ans. Sans cette date, l'outil considère qu'aucun entretien n'a eu lieu, affiche un retard et une alerte.
B7: ③ Journal – Consignez chaque nouvel entretien réalisé (matricule, date, type). La date la plus récente entre la colonne L et le Journal est retenue automatiquement : inutile de ressaisir la date dans le Suivi. Un entretien de type « EPP + état des lieux récapitulatif » ou « Bilan à 6 ans » relance aussi le cycle de 8 ans.
B8: ④ Tableau de bord – Vue d'ensemble des retards, contrôles de saisie, cas particuliers, exposition à l'abondement correctif, répartition par service et plan de charge sur 12 mois.
B9: ⑤ Les lignes EX-001 à EX-012 (Suivi) et les lignes EX-… du Journal sont des exemples fictifs illustrant chaque cas : effacez le contenu de leurs cellules jaunes (touche Suppr) sans supprimer les lignes, afin de conserver les formules. L'outil est préformaté pour 500 salariés et 1 000 entretiens.
B10: La date de référence (Paramètres) est par défaut la date du jour : tous les statuts se mettent à jour à chaque ouverture du fichier.
B12: 2. RÈGLES DE CALCUL APPLIQUÉES
B13: Situation | C13: Règle appliquée par l'outil | D13: Référence
B14: Salarié de moins d'un an, sans entretien | C14: 1er EPP au plus tard 12 mois après la date d'embauche. | D14: L6315-1 : EPP « au cours de la première année suivant son embauche »
B15: Salarié de plus d'un an (ou 1er EPP déjà réalisé) | C15: Prochain EPP = date du précédent entretien professionnel (ou du dernier EPP) + 4 ans. | D15: L6315-1 ; le délai de 4 ans court à compter du dernier entretien réalisé
B16: Précédent entretien dont le délai de 2 ans était déjà expiré au 26/10/2025 | C16: L'échéance reste fixée à précédent entretien + 2 ans : le salarié apparaît en retard et l'EPP est à organiser sans attendre. Règle désactivable dans les Paramètres. | D16: Règle transitoire (délais non expirés prolongés)
B17: Salarié de plus d'un an sans date de précédent entretien | C17: Échéance = embauche + 12 mois (donc dépassée) + alerte « Précédent entretien à renseigner ». | D17: Contrôle de saisie
B18: Reprise après une absence | C18: EPP proposé à la reprise (congé de maternité, d'adoption, parental d'éducation ou temps partiel parental, proche aidant, sabbatique, mobilité volontaire sécurisée, arrêt longue maladie, mandat syndical), sauf si un EPP a eu lieu dans les 12 mois précédant la reprise (« Dispensé »). | D18: L6315-1
B19: Visite médicale de mi-carrière | C19: EPP à organiser dans les 2 mois suivant la visite. Alerte si le salarié a 44 à 46 ans (année civile) sans visite renseignée. | D19: L6315-1 ; L4624-2-2
B20: Approche des 60 ans | C20: Le 1er EPP intervenant dans les 2 ans précédant le 60e anniversaire aborde le maintien dans l'emploi et les aménagements de fin de carrière (temps partiel, retraite progressive). L'outil signale si le prochain EPP tomberait après les 60 ans (« À programmer avant 60 ans »). | D20: L6315-1
B21: État des lieux récapitulatif | C21: Tous les 8 ans à compter de l'embauche ou du dernier état des lieux / bilan. Si le bilan à 6 ans était déjà échu au 26/10/2025, l'échéance reste l'ancienne (retard) ; sinon elle est reportée à 8 ans. | D21: L6315-1
B22: Abondement correctif du CPF | C22: Entreprises d'au moins 50 salariés : 3 000 € versés sur le CPF si, sur le cycle, le salarié n'a pas bénéficié des entretiens prévus et d'au moins une formation non obligatoire. | D22: L6323-13 ; R6323-3
B24: 3. STATUTS ET CODES COULEUR
B25: Statut | C25: Signification | D25: Colonnes concernées
B26: En retard / Non réalisé | C26: Échéance dépassée : entretien à organiser en priorité. | D26: Statut EPP, mi-carrière, fin de carrière, état des lieux
B27: À planifier / À prévoir | C27: Échéance dans moins de 90 jours (EPP) ou 180 jours (état des lieux). | D27: Statut EPP, mi-carrière, état des lieux, reprise
B28: Planifié | C28: Une date de convocation est fixée avant l'échéance. | D28: Statut EPP, fin de carrière
B29: À jour / Réalisé | C29: Aucune action requise à ce jour. | D29: Toutes
B30: Dispensé (EPP récent) | C30: Reprise d'absence : un EPP a eu lieu dans les 12 mois précédant la reprise. | D30: EPP de reprise
B31: Risque abondement | C31: Ni les entretiens prévus ni une formation non obligatoire sur le cycle (≥ 50 salariés). | D31: Risque abondement CPF
B32: Sorti / Non concerné | C32: Salarié parti, ou obligation non applicable. | D32: Toutes
B34: 4. POINTS DE VIGILANCE ET HYPOTHÈSES
B35: • L'EPP porte sur les perspectives d'évolution professionnelle (compétences, qualifications, formation, mobilité, reconversion, CPF, VAE, conseil en évolution professionnelle…) et jamais sur l'évaluation du travail du salarié : il reste distinct de l'entretien annuel d'évaluation. Il se tient sur le temps de travail et donne lieu à un document écrit dont une copie est remise au salarié (colonne « Compte rendu écrit remis ? » du Journal).
B36: • Accords collectifs : si un accord d'entreprise ou de branche aménage l'EPP, adaptez les paramètres. Les accords antérieurs prévoyant une périodicité supérieure à 4 ans devaient être mis en conformité au plus tard le 1er octobre 2026.
B37: • Salariés embauchés avant le 26/10/2025 et n'ayant encore eu aucun entretien : par prudence, l'outil applique le délai d'un an de la nouvelle loi.
B38: • Fenêtre des 58-60 ans : interprétation prudente – si aucun EPP n'est prévu dans la fenêtre, l'outil recommande d'en programmer un.
B39: • Abondement correctif : le critère retenu (absence cumulée des entretiens prévus et de toute formation non obligatoire) suit la lecture administrative de l'article L6323-13 ; vérifiez-le au regard des textes et précisions ministérielles en vigueur.
B40: • Cet outil est une aide au pilotage : il ne remplace pas l'analyse juridique de situations particulières (transferts de contrats, suspensions multiples, accords spécifiques). Référez-vous au texte en vigueur sur Légifrance.

Sheet Tableau de bord
B1: Tableau de bord – Entretiens de parcours professionnel
B2: Date de référence : | C2: =DateRef -> 46288
B3: Effectif déclaré (Paramètres) : | C3: =Effectif -> 60
B5: ENTRETIENS DE PARCOURS PROFESSIONNEL | E5: RÉPARTITION PAR SERVICE
B6: Salariés actifs suivis | C6: =COUNTIF('Suivi EPP'!$S$6:$S$505,"En retard")+COUNTIF('Suivi EPP'!$S$6:$S$505,"À planifier")+COUNTIF('Suivi EPP'!$S$6:$S$505,"Planifié")+COUNTIF('Suivi EPP'!$S$6:$S$505,"À jour")+COUNTIF('Suivi EPP'!$S$6:$S$505,"À compléter") -> 11 | E6: Service | F6: Actifs | G6: En retard | H6: À planifier | I6: Planifiés | J6: À jour | K6: Conformité
B7: dont ancienneté de moins d'un an | C7: =COUNTIFS('Suivi EPP'!$K$6:$K$505,"Moins d'un an",'Suivi EPP'!$S$6:$S$505,"<>Sorti") -> 2 | E7: =IF(Paramètres!G5="","",Paramètres!G5) -> Direction | F7: =IF($E7="","",COUNTIFS('Suivi EPP'!$D$6:$D$505,$E7)-COUNTIFS('Suivi EPP'!$D$6:$D$505,$E7,'Suivi EPP'!$S$6:$S$505,"Sorti")) -> 0 | G7: =IF($E7="","",COUNTIFS('Suivi EPP'!$D$6:$D$505,$E7,'Suivi EPP'!$S$6:$S$505,"En retard")) -> 0 | H7: =IF($E7="","",COUNTIFS('Suivi EPP'!$D$6:$D$505,$E7,'Suivi EPP'!$S$6:$S$505,"À planifier")) -> 0 | I7: =IF($E7="","",COUNTIFS('Suivi EPP'!$D$6:$D$505,$E7,'Suivi EPP'!$S$6:$S$505,"Planifié")) -> 0 | J7: =IF($E7="","",COUNTIFS('Suivi EPP'!$D$6:$D$505,$E7,'Suivi EPP'!$S$6:$S$505,"À jour")) -> 0 | K7: =IF(OR($E7="",N($F7)=0),"",1-$G7/$F7)
B8: dont ancienneté de plus d'un an | C8: =COUNTIFS('Suivi EPP'!$K$6:$K$505,"Plus d'un an",'Suivi EPP'!$S$6:$S$505,"<>Sorti") -> 9 | E8: =IF(Paramètres!G6="","",Paramètres!G6) -> Ressources humaines | F8: =IF($E8="","",COUNTIFS('Suivi EPP'!$D$6:$D$505,$E8)-COUNTIFS('Suivi EPP'!$D$6:$D$505,$E8,'Suivi EPP'!$S$6:$S$505,"Sorti")) -> 1 | G8: =IF($E8="","",COUNTIFS('Suivi EPP'!$D$6:$D$505,$E8,'Suivi EPP'!$S$6:$S$505,"En retard")) -> 1 | H8: =IF($E8="","",COUNTIFS('Suivi EPP'!$D$6:$D$505,$E8,'Suivi EPP'!$S$6:$S$505,"À planifier")) -> 0 | I8: =IF($E8="","",COUNTIFS('Suivi EPP'!$D$6:$D$505,$E8,'Suivi EPP'!$S$6:$S$505,"Planifié")) -> 0 | J8: =IF($E8="","",COUNTIFS('Suivi EPP'!$D$6:$D$505,$E8,'Suivi EPP'!$S$6:$S$505,"À jour")) -> 0 | K8: =IF(OR($E8="",N($F8)=0),"",1-$G8/$F8) -> 0
B9: EPP en retard | C9: =COUNTIF('Suivi EPP'!$S$6:$S$505,"En retard") -> 2 | E9: =IF(Paramètres!G7="","",Paramètres!G7) -> Administratif et finance | F9: =IF($E9="","",COUNTIFS('Suivi EPP'!$D$6:$D$505,$E9)-COUNTIFS('Suivi EPP'!$D$6:$D$505,$E9,'Suivi EPP'!$S$6:$S$505,"Sorti")) -> 1 | G9: =IF($E9="","",COUNTIFS('Suivi EPP'!$D$6:$D$505,$E9,'Suivi EPP'!$S$6:$S$505,"En retard")) -> 0 | H9: =IF($E9="","",COUNTIFS('Suivi EPP'!$D$6:$D$505,$E9,'Suivi EPP'!$S$6:$S$505,"À planifier")) -> 0 | I9: =IF($E9="","",COUNTIFS('Suivi EPP'!$D$6:$D$505,$E9,'Suivi EPP'!$S$6:$S$505,"Planifié")) -> 0 | J9: =IF($E9="","",COUNTIFS('Suivi EPP'!$D$6:$D$505,$E9,'Suivi EPP'!$S$6:$S$505,"À jour")) -> 1 | K9: =IF(OR($E9="",N($F9)=0),"",1-$G9/$F9) -> 1
B10: ="EPP à planifier (échéance ≤ "&SeuilAlerteEPP&" jours)" -> EPP à planifier (échéance ≤ 90 jours) | C10: =COUNTIF('Suivi EPP'!$S$6:$S$505,"À planifier") -> 0 | E10: =IF(Paramètres!G8="","",Paramètres!G8) -> Commercial | F10: =IF($E10="","",COUNTIFS('Suivi EPP'!$D$6:$D$505,$E10)-COUNTIFS('Suivi EPP'!$D$6:$D$505,$E10,'Suivi EPP'!$S$6:$S$505,"Sorti")) -> 3 | G10: =IF($E10="","",COUNTIFS('Suivi EPP'!$D$6:$D$505,$E10,'Suivi EPP'!$S$6:$S$505,"En retard")) -> 0 | H10: =IF($E10="","",COUNTIFS('Suivi EPP'!$D$6:$D$505,$E10,'Suivi EPP'!$S$6:$S$505,"À planifier")) -> 0 | I10: =IF($E10="","",COUNTIFS('Suivi EPP'!$D$6:$D$505,$E10,'Suivi EPP'!$S$6:$S$505,"Planifié")) -> 1 | J10: =IF($E10="","",COUNTIFS('Suivi EPP'!$D$6:$D$505,$E10,'Suivi EPP'!$S$6:$S$505,"À jour")) -> 2 | K10: =IF(OR($E10="",N($F10)=0),"",1-$G10/$F10) -> 1
B11: EPP planifiés | C11: =COUNTIF('Suivi EPP'!$S$6:$S$505,"Planifié") -> 1 | E11: =IF(Paramètres!G9="","",Paramètres!G9) -> Production | F11: =IF($E11="","",COUNTIFS('Suivi EPP'!$D$6:$D$505,$E11)-COUNTIFS('Suivi EPP'!$D$6:$D$505,$E11,'Suivi EPP'!$S$6:$S$505,"Sorti")) -> 2 | G11: =IF($E11="","",COUNTIFS('Suivi EPP'!$D$6:$D$505,$E11,'Suivi EPP'!$S$6:$S$505,"En retard")) -> 0 | H11: =IF($E11="","",COUNTIFS('Suivi EPP'!$D$6:$D$505,$E11,'Suivi EPP'!$S$6:$S$505,"À planifier")) -> 0 | I11: =IF($E11="","",COUNTIFS('Suivi EPP'!$D$6:$D$505,$E11,'Suivi EPP'!$S$6:$S$505,"Planifié")) -> 0 | J11: =IF($E11="","",COUNTIFS('Suivi EPP'!$D$6:$D$505,$E11,'Suivi EPP'!$S$6:$S$505,"À jour")) -> 2 | K11: =IF(OR($E11="",N($F11)=0),"",1-$G11/$F11) -> 1
B12: EPP à jour | C12: =COUNTIF('Suivi EPP'!$S$6:$S$505,"À jour") -> 8 | E12: =IF(Paramètres!G10="","",Paramètres!G10) -> Logistique | F12: =IF($E12="","",COUNTIFS('Suivi EPP'!$D$6:$D$505,$E12)-COUNTIFS('Suivi EPP'!$D$6:$D$505,$E12,'Suivi EPP'!$S$6:$S$505,"Sorti")) -> 2 | G12: =IF($E12="","",COUNTIFS('Suivi EPP'!$D$6:$D$505,$E12,'Suivi EPP'!$S$6:$S$505,"En retard")) -> 0 | H12: =IF($E12="","",COUNTIFS('Suivi EPP'!$D$6:$D$505,$E12,'Suivi EPP'!$S$6:$S$505,"À planifier")) -> 0 | I12: =IF($E12="","",COUNTIFS('Suivi EPP'!$D$6:$D$505,$E12,'Suivi EPP'!$S$6:$S$505,"Planifié")) -> 0 | J12: =IF($E12="","",COUNTIFS('Suivi EPP'!$D$6:$D$505,$E12,'Suivi EPP'!$S$6:$S$505,"À jour")) -> 2 | K12: =IF(OR($E12="",N($F12)=0),"",1-$G12/$F12) -> 1
B13: Taux de conformité (salariés actifs sans retard) | C13: =IF(C6=0,"",1-C9/C6) -> 0.81818182 | E13: =IF(Paramètres!G11="","",Paramètres!G11) -> Informatique | F13: =IF($E13="","",COUNTIFS('Suivi EPP'!$D$6:$D$505,$E13)-COUNTIFS('Suivi EPP'!$D$6:$D$505,$E13,'Suivi EPP'!$S$6:$S$505,"Sorti")) -> 2 | G13: =IF($E13="","",COUNTIFS('Suivi EPP'!$D$6:$D$505,$E13,'Suivi EPP'!$S$6:$S$505,"En retard")) -> 1 | H13: =IF($E13="","",COUNTIFS('Suivi EPP'!$D$6:$D$505,$E13,'Suivi EPP'!$S$6:$S$505,"À planifier")) -> 0 | I13: =IF($E13="","",COUNTIFS('Suivi EPP'!$D$6:$D$505,$E13,'Suivi EPP'!$S$6:$S$505,"Planifié")) -> 0 | J13: =IF($E13="","",COUNTIFS('Suivi EPP'!$D$6:$D$505,$E13,'Suivi EPP'!$S$6:$S$505,"À jour")) -> 1 | K13: =IF(OR($E13="",N($F13)=0),"",1-$G13/$F13) -> 0.5
E14: =IF(Paramètres!G12="","",Paramètres!G12) -> Qualité | F14: =IF($E14="","",COUNTIFS('Suivi EPP'!$D$6:$D$505,$E14)-COUNTIFS('Suivi EPP'!$D$6:$D$505,$E14,'Suivi EPP'!$S$6:$S$505,"Sorti")) -> 0 | G14: =IF($E14="","",COUNTIFS('Suivi EPP'!$D$6:$D$505,$E14,'Suivi EPP'!$S$6:$S$505,"En retard")) -> 0 | H14: =IF($E14="","",COUNTIFS('Suivi EPP'!$D$6:$D$505,$E14,'Suivi EPP'!$S$6:$S$505,"À planifier")) -> 0 | I14: =IF($E14="","",COUNTIFS('Suivi EPP'!$D$6:$D$505,$E14,'Suivi EPP'!$S$6:$S$505,"Planifié")) -> 0 | J14: =IF($E14="","",COUNTIFS('Suivi EPP'!$D$6:$D$505,$E14,'Suivi EPP'!$S$6:$S$505,"À jour")) -> 0 | K14: =IF(OR($E14="",N($F14)=0),"",1-$G14/$F14)
B15: CONTRÔLES DE SAISIE | E15: =IF(Paramètres!G13="","",Paramètres!G13) | F15: =IF($E15="","",COUNTIFS('Suivi EPP'!$D$6:$D$505,$E15)-COUNTIFS('Suivi EPP'!$D$6:$D$505,$E15,'Suivi EPP'!$S$6:$S$505,"Sorti")) | G15: =IF($E15="","",COUNTIFS('Suivi EPP'!$D$6:$D$505,$E15,'Suivi EPP'!$S$6:$S$505,"En retard")) | H15: =IF($E15="","",COUNTIFS('Suivi EPP'!$D$6:$D$505,$E15,'Suivi EPP'!$S$6:$S$505,"À planifier")) | I15: =IF($E15="","",COUNTIFS('Suivi EPP'!$D$6:$D$505,$E15,'Suivi EPP'!$S$6:$S$505,"Planifié")) | J15: =IF($E15="","",COUNTIFS('Suivi EPP'!$D$6:$D$505,$E15,'Suivi EPP'!$S$6:$S$505,"À jour")) | K15: =IF(OR($E15="",N($F15)=0),"",1-$G15/$F15)
B16: Salariés de plus d'un an sans date de précédent entretien | C16: =COUNTIFS('Suivi EPP'!$K$6:$K$505,"Plus d'un an",'Suivi EPP'!$N$6:$N$505,"",'Suivi EPP'!$S$6:$S$505,"<>Sorti") -> 1 | E16: =IF(Paramètres!G14="","",Paramètres!G14) | F16: =IF($E16="","",COUNTIFS('Suivi EPP'!$D$6:$D$505,$E16)-COUNTIFS('Suivi EPP'!$D$6:$D$505,$E16,'Suivi EPP'!$S$6:$S$505,"Sorti")) | G16: =IF($E16="","",COUNTIFS('Suivi EPP'!$D$6:$D$505,$E16,'Suivi EPP'!$S$6:$S$505,"En retard")) | H16: =IF($E16="","",COUNTIFS('Suivi EPP'!$D$6:$D$505,$E16,'Suivi EPP'!$S$6:$S$505,"À planifier")) | I16: =IF($E16="","",COUNTIFS('Suivi EPP'!$D$6:$D$505,$E16,'Suivi EPP'!$S$6:$S$505,"Planifié")) | J16: =IF($E16="","",COUNTIFS('Suivi EPP'!$D$6:$D$505,$E16,'Suivi EPP'!$S$6:$S$505,"À jour")) | K16: =IF(OR($E16="",N($F16)=0),"",1-$G16/$F16)
B17: Lignes comportant au moins une alerte | C17: =SUMPRODUCT((LEN('Suivi EPP'!$T$6:$T$505)>0)*1) -> 3 | E17: =IF(Paramètres!G15="","",Paramètres!G15) | F17: =IF($E17="","",COUNTIFS('Suivi EPP'!$D$6:$D$505,$E17)-COUNTIFS('Suivi EPP'!$D$6:$D$505,$E17,'Suivi EPP'!$S$6:$S$505,"Sorti")) | G17: =IF($E17="","",COUNTIFS('Suivi EPP'!$D$6:$D$505,$E17,'Suivi EPP'!$S$6:$S$505,"En retard")) | H17: =IF($E17="","",COUNTIFS('Suivi EPP'!$D$6:$D$505,$E17,'Suivi EPP'!$S$6:$S$505,"À planifier")) | I17: =IF($E17="","",COUNTIFS('Suivi EPP'!$D$6:$D$505,$E17,'Suivi EPP'!$S$6:$S$505,"Planifié")) | J17: =IF($E17="","",COUNTIFS('Suivi EPP'!$D$6:$D$505,$E17,'Suivi EPP'!$S$6:$S$505,"À jour")) | K17: =IF(OR($E17="",N($F17)=0),"",1-$G17/$F17)
B18: Fiches incomplètes (date d'embauche manquante) | C18: =COUNTIF('Suivi EPP'!$S$6:$S$505,"À compléter") -> 0 | E18: =IF(Paramètres!G16="","",Paramètres!G16) | F18: =IF($E18="","",COUNTIFS('Suivi EPP'!$D$6:$D$505,$E18)-COUNTIFS('Suivi EPP'!$D$6:$D$505,$E18,'Suivi EPP'!$S$6:$S$505,"Sorti")) | G18: =IF($E18="","",COUNTIFS('Suivi EPP'!$D$6:$D$505,$E18,'Suivi EPP'!$S$6:$S$505,"En retard")) | H18: =IF($E18="","",COUNTIFS('Suivi EPP'!$D$6:$D$505,$E18,'Suivi EPP'!$S$6:$S$505,"À planifier")) | I18: =IF($E18="","",COUNTIFS('Suivi EPP'!$D$6:$D$505,$E18,'Suivi EPP'!$S$6:$S$505,"Planifié")) | J18: =IF($E18="","",COUNTIFS('Suivi EPP'!$D$6:$D$505,$E18,'Suivi EPP'!$S$6:$S$505,"À jour")) | K18: =IF(OR($E18="",N($F18)=0),"",1-$G18/$F18)
E19: =IF(Paramètres!G17="","",Paramètres!G17) | F19: =IF($E19="","",COUNTIFS('Suivi EPP'!$D$6:$D$505,$E19)-COUNTIFS('Suivi EPP'!$D$6:$D$505,$E19,'Suivi EPP'!$S$6:$S$505,"Sorti")) | G19: =IF($E19="","",COUNTIFS('Suivi EPP'!$D$6:$D$505,$E19,'Suivi EPP'!$S$6:$S$505,"En retard")) | H19: =IF($E19="","",COUNTIFS('Suivi EPP'!$D$6:$D$505,$E19,'Suivi EPP'!$S$6:$S$505,"À planifier")) | I19: =IF($E19="","",COUNTIFS('Suivi EPP'!$D$6:$D$505,$E19,'Suivi EPP'!$S$6:$S$505,"Planifié")) | J19: =IF($E19="","",COUNTIFS('Suivi EPP'!$D$6:$D$505,$E19,'Suivi EPP'!$S$6:$S$505,"À jour")) | K19: =IF(OR($E19="",N($F19)=0),"",1-$G19/$F19)
B20: CAS PARTICULIERS | E20: =IF(Paramètres!G18="","",Paramètres!G18) | F20: =IF($E20="","",COUNTIFS('Suivi EPP'!$D$6:$D$505,$E20)-COUNTIFS('Suivi EPP'!$D$6:$D$505,$E20,'Suivi EPP'!$S$6:$S$505,"Sorti")) | G20: =IF($E20="","",COUNTIFS('Suivi EPP'!$D$6:$D$505,$E20,'Suivi EPP'!$S$6:$S$505,"En retard")) | H20: =IF($E20="","",COUNTIFS('Suivi EPP'!$D$6:$D$505,$E20,'Suivi EPP'!$S$6:$S$505,"À planifier")) | I20: =IF($E20="","",COUNTIFS('Suivi EPP'!$D$6:$D$505,$E20,'Suivi EPP'!$S$6:$S$505,"Planifié")) | J20: =IF($E20="","",COUNTIFS('Suivi EPP'!$D$6:$D$505,$E20,'Suivi EPP'!$S$6:$S$505,"À jour")) | K20: =IF(OR($E20="",N($F20)=0),"",1-$G20/$F20)
B21: Reprise d'absence : EPP à proposer (reprise passée) | C21: =COUNTIF('Suivi EPP'!$W$6:$W$505,"À proposer (reprise passée)") -> 1 | E21: =IF(Paramètres!G19="","",Paramètres!G19) | F21: =IF($E21="","",COUNTIFS('Suivi EPP'!$D$6:$D$505,$E21)-COUNTIFS('Suivi EPP'!$D$6:$D$505,$E21,'Suivi EPP'!$S$6:$S$505,"Sorti")) | G21: =IF($E21="","",COUNTIFS('Suivi EPP'!$D$6:$D$505,$E21,'Suivi EPP'!$S$6:$S$505,"En retard")) | H21: =IF($E21="","",COUNTIFS('Suivi EPP'!$D$6:$D$505,$E21,'Suivi EPP'!$S$6:$S$505,"À planifier")) | I21: =IF($E21="","",COUNTIFS('Suivi EPP'!$D$6:$D$505,$E21,'Suivi EPP'!$S$6:$S$505,"Planifié")) | J21: =IF($E21="","",COUNTIFS('Suivi EPP'!$D$6:$D$505,$E21,'Suivi EPP'!$S$6:$S$505,"À jour")) | K21: =IF(OR($E21="",N($F21)=0),"",1-$G21/$F21)
B22: Reprise d'absence : EPP à prévoir à la reprise | C22: =COUNTIF('Suivi EPP'!$W$6:$W$505,"À prévoir à la reprise") -> 1 | E22: =IF(Paramètres!G20="","",Paramètres!G20) | F22: =IF($E22="","",COUNTIFS('Suivi EPP'!$D$6:$D$505,$E22)-COUNTIFS('Suivi EPP'!$D$6:$D$505,$E22,'Suivi EPP'!$S$6:$S$505,"Sorti")) | G22: =IF($E22="","",COUNTIFS('Suivi EPP'!$D$6:$D$505,$E22,'Suivi EPP'!$S$6:$S$505,"En retard")) | H22: =IF($E22="","",COUNTIFS('Suivi EPP'!$D$6:$D$505,$E22,'Suivi EPP'!$S$6:$S$505,"À planifier")) | I22: =IF($E22="","",COUNTIFS('Suivi EPP'!$D$6:$D$505,$E22,'Suivi EPP'!$S$6:$S$505,"Planifié")) | J22: =IF($E22="","",COUNTIFS('Suivi EPP'!$D$6:$D$505,$E22,'Suivi EPP'!$S$6:$S$505,"À jour")) | K22: =IF(OR($E22="",N($F22)=0),"",1-$G22/$F22)
B23: Mi-carrière : EPP post-visite en retard | C23: =COUNTIF('Suivi EPP'!$Z$6:$Z$505,"En retard") -> 0 | E23: =IF(Paramètres!G21="","",Paramètres!G21) | F23: =IF($E23="","",COUNTIFS('Suivi EPP'!$D$6:$D$505,$E23)-COUNTIFS('Suivi EPP'!$D$6:$D$505,$E23,'Suivi EPP'!$S$6:$S$505,"Sorti")) | G23: =IF($E23="","",COUNTIFS('Suivi EPP'!$D$6:$D$505,$E23,'Suivi EPP'!$S$6:$S$505,"En retard")) | H23: =IF($E23="","",COUNTIFS('Suivi EPP'!$D$6:$D$505,$E23,'Suivi EPP'!$S$6:$S$505,"À planifier")) | I23: =IF($E23="","",COUNTIFS('Suivi EPP'!$D$6:$D$505,$E23,'Suivi EPP'!$S$6:$S$505,"Planifié")) | J23: =IF($E23="","",COUNTIFS('Suivi EPP'!$D$6:$D$505,$E23,'Suivi EPP'!$S$6:$S$505,"À jour")) | K23: =IF(OR($E23="",N($F23)=0),"",1-$G23/$F23)
B24: Mi-carrière : EPP post-visite à planifier | C24: =COUNTIF('Suivi EPP'!$Z$6:$Z$505,"À planifier") -> 1 | E24: =IF(Paramètres!G22="","",Paramètres!G22) | F24: =IF($E24="","",COUNTIFS('Suivi EPP'!$D$6:$D$505,$E24)-COUNTIFS('Suivi EPP'!$D$6:$D$505,$E24,'Suivi EPP'!$S$6:$S$505,"Sorti")) | G24: =IF($E24="","",COUNTIFS('Suivi EPP'!$D$6:$D$505,$E24,'Suivi EPP'!$S$6:$S$505,"En retard")) | H24: =IF($E24="","",COUNTIFS('Suivi EPP'!$D$6:$D$505,$E24,'Suivi EPP'!$S$6:$S$505,"À planifier")) | I24: =IF($E24="","",COUNTIFS('Suivi EPP'!$D$6:$D$505,$E24,'Suivi EPP'!$S$6:$S$505,"Planifié")) | J24: =IF($E24="","",COUNTIFS('Suivi EPP'!$D$6:$D$505,$E24,'Suivi EPP'!$S$6:$S$505,"À jour")) | K24: =IF(OR($E24="",N($F24)=0),"",1-$G24/$F24)
B25: Fin de carrière : EPP à programmer avant 60 ans | C25: =COUNTIF('Suivi EPP'!$AC$6:$AC$505,"À programmer avant 60 ans") -> 1 | E25: =IF(Paramètres!G23="","",Paramètres!G23) | F25: =IF($E25="","",COUNTIFS('Suivi EPP'!$D$6:$D$505,$E25)-COUNTIFS('Suivi EPP'!$D$6:$D$505,$E25,'Suivi EPP'!$S$6:$S$505,"Sorti")) | G25: =IF($E25="","",COUNTIFS('Suivi EPP'!$D$6:$D$505,$E25,'Suivi EPP'!$S$6:$S$505,"En retard")) | H25: =IF($E25="","",COUNTIFS('Suivi EPP'!$D$6:$D$505,$E25,'Suivi EPP'!$S$6:$S$505,"À planifier")) | I25: =IF($E25="","",COUNTIFS('Suivi EPP'!$D$6:$D$505,$E25,'Suivi EPP'!$S$6:$S$505,"Planifié")) | J25: =IF($E25="","",COUNTIFS('Suivi EPP'!$D$6:$D$505,$E25,'Suivi EPP'!$S$6:$S$505,"À jour")) | K25: =IF(OR($E25="",N($F25)=0),"",1-$G25/$F25)
B26: Fin de carrière : EPP non réalisé avant 60 ans | C26: =COUNTIF('Suivi EPP'!$AC$6:$AC$505,"Non réalisé") -> 0 | E26: =IF(Paramètres!G24="","",Paramètres!G24) | F26: =IF($E26="","",COUNTIFS('Suivi EPP'!$D$6:$D$505,$E26)-COUNTIFS('Suivi EPP'!$D$6:$D$505,$E26,'Suivi EPP'!$S$6:$S$505,"Sorti")) | G26: =IF($E26="","",COUNTIFS('Suivi EPP'!$D$6:$D$505,$E26,'Suivi EPP'!$S$6:$S$505,"En retard")) | H26: =IF($E26="","",COUNTIFS('Suivi EPP'!$D$6:$D$505,$E26,'Suivi EPP'!$S$6:$S$505,"À planifier")) | I26: =IF($E26="","",COUNTIFS('Suivi EPP'!$D$6:$D$505,$E26,'Suivi EPP'!$S$6:$S$505,"Planifié")) | J26: =IF($E26="","",COUNTIFS('Suivi EPP'!$D$6:$D$505,$E26,'Suivi EPP'!$S$6:$S$505,"À jour")) | K26: =IF(OR($E26="",N($F26)=0),"",1-$G26/$F26)
E27: Total | F27: =SUM(F7:F26) -> 11 | G27: =SUM(G7:G26) -> 2 | H27: =SUM(H7:H26) -> 0 | I27: =SUM(I7:I26) -> 1 | J27: =SUM(J7:J26) -> 8 | K27: =IF(F27=0,"",1-G27/F27) -> 0.81818182
B28: ÉTAT DES LIEUX RÉCAPITULATIF & ABONDEMENT CPF | E28: =IF(F27<>C6,"Écart avec le total : "&(C6-F27)&" salarié(s) sans service reconnu","")
B29: États des lieux en retard | C29: =COUNTIF('Suivi EPP'!$AG$6:$AG$505,"En retard") -> 2
B30: ="États des lieux à prévoir (≤ "&SeuilAlerteEDL&" jours)" -> États des lieux à prévoir (≤ 180 jours) | C30: =COUNTIF('Suivi EPP'!$AG$6:$AG$505,"À prévoir") -> 0 | E30: PLAN DE CHARGE – 12 PROCHAINS MOIS
B31: Salariés exposés au risque d'abondement correctif | C31: =COUNTIF('Suivi EPP'!$AJ$6:$AJ$505,"Risque abondement") -> 1 | E31: Mois | F31: Du | G31: Au | H31: EPP à échéance | I31: EPP planifiés | J31: États des lieux
B32: Situations à vérifier (formation non renseignée) | C32: =COUNTIF('Suivi EPP'!$AJ$6:$AJ$505,"À vérifier (formation ?)") -> 1 | E32: Retard à résorber | H32: =COUNTIF('Suivi EPP'!$S$6:$S$505,"En retard") -> 2 | J32: =COUNTIF('Suivi EPP'!$AG$6:$AG$505,"En retard") -> 2
B33: Exposition financière potentielle | C33: =IF(Effectif<SeuilEffectif,0,C31*MontantAbondement) -> 3000 | E33: =F33 -> 46288 | F33: =DateRef -> 46288 | G33: =EOMONTH(DateRef,0) -> 46295 | H33: =COUNTIFS('Suivi EPP'!$P$6:$P$505,">="&$F33,'Suivi EPP'!$P$6:$P$505,"<="&$G33,'Suivi EPP'!$S$6:$S$505,"<>Sorti") -> 0 | I33: =COUNTIFS('Suivi EPP'!$Q$6:$Q$505,">="&$F33,'Suivi EPP'!$Q$6:$Q$505,"<="&$G33,'Suivi EPP'!$S$6:$S$505,"<>Sorti") -> 0 | J33: =COUNTIFS('Suivi EPP'!$AF$6:$AF$505,">="&$F33,'Suivi EPP'!$AF$6:$AF$505,"<="&$G33,'Suivi EPP'!$S$6:$S$505,"<>Sorti") -> 0
E34: =F34 -> 46296 | F34: =EOMONTH(DateRef,0)+1 -> 46296 | G34: =EOMONTH(DateRef,1) -> 46326 | H34: =COUNTIFS('Suivi EPP'!$P$6:$P$505,">="&$F34,'Suivi EPP'!$P$6:$P$505,"<="&$G34,'Suivi EPP'!$S$6:$S$505,"<>Sorti") -> 0 | I34: =COUNTIFS('Suivi EPP'!$Q$6:$Q$505,">="&$F34,'Suivi EPP'!$Q$6:$Q$505,"<="&$G34,'Suivi EPP'!$S$6:$S$505,"<>Sorti") -> 1 | J34: =COUNTIFS('Suivi EPP'!$AF$6:$AF$505,">="&$F34,'Suivi EPP'!$AF$6:$AF$505,"<="&$G34,'Suivi EPP'!$S$6:$S$505,"<>Sorti") -> 0
E35: =F35 -> 46327 | F35: =EOMONTH(DateRef,1)+1 -> 46327 | G35: =EOMONTH(DateRef,2) -> 46356 | H35: =COUNTIFS('Suivi EPP'!$P$6:$P$505,">="&$F35,'Suivi EPP'!$P$6:$P$505,"<="&$G35,'Suivi EPP'!$S$6:$S$505,"<>Sorti") -> 1 | I35: =COUNTIFS('Suivi EPP'!$Q$6:$Q$505,">="&$F35,'Suivi EPP'!$Q$6:$Q$505,"<="&$G35,'Suivi EPP'!$S$6:$S$505,"<>Sorti") -> 0 | J35: =COUNTIFS('Suivi EPP'!$AF$6:$AF$505,">="&$F35,'Suivi EPP'!$AF$6:$AF$505,"<="&$G35,'Suivi EPP'!$S$6:$S$505,"<>Sorti") -> 0
E36: =F36 -> 46357 | F36: =EOMONTH(DateRef,2)+1 -> 46357 | G36: =EOMONTH(DateRef,3) -> 46387 | H36: =COUNTIFS('Suivi EPP'!$P$6:$P$505,">="&$F36,'Suivi EPP'!$P$6:$P$505,"<="&$G36,'Suivi EPP'!$S$6:$S$505,"<>Sorti") -> 0 | I36: =COUNTIFS('Suivi EPP'!$Q$6:$Q$505,">="&$F36,'Suivi EPP'!$Q$6:$Q$505,"<="&$G36,'Suivi EPP'!$S$6:$S$505,"<>Sorti") -> 0 | J36: =COUNTIFS('Suivi EPP'!$AF$6:$AF$505,">="&$F36,'Suivi EPP'!$AF$6:$AF$505,"<="&$G36,'Suivi EPP'!$S$6:$S$505,"<>Sorti") -> 0
E37: =F37 -> 46388 | F37: =EOMONTH(DateRef,3)+1 -> 46388 | G37: =EOMONTH(DateRef,4) -> 46418 | H37: =COUNTIFS('Suivi EPP'!$P$6:$P$505,">="&$F37,'Suivi EPP'!$P$6:$P$505,"<="&$G37,'Suivi EPP'!$S$6:$S$505,"<>Sorti") -> 0 | I37: =COUNTIFS('Suivi EPP'!$Q$6:$Q$505,">="&$F37,'Suivi EPP'!$Q$6:$Q$505,"<="&$G37,'Suivi EPP'!$S$6:$S$505,"<>Sorti") -> 0 | J37: =COUNTIFS('Suivi EPP'!$AF$6:$AF$505,">="&$F37,'Suivi EPP'!$AF$6:$AF$505,"<="&$G37,'Suivi EPP'!$S$6:$S$505,"<>Sorti") -> 0
E38: =F38 -> 46419 | F38: =EOMONTH(DateRef,4)+1 -> 46419 | G38: =EOMONTH(DateRef,5) -> 46446 | H38: =COUNTIFS('Suivi EPP'!$P$6:$P$505,">="&$F38,'Suivi EPP'!$P$6:$P$505,"<="&$G38,'Suivi EPP'!$S$6:$S$505,"<>Sorti") -> 1 | I38: =COUNTIFS('Suivi EPP'!$Q$6:$Q$505,">="&$F38,'Suivi EPP'!$Q$6:$Q$505,"<="&$G38,'Suivi EPP'!$S$6:$S$505,"<>Sorti") -> 0 | J38: =COUNTIFS('Suivi EPP'!$AF$6:$AF$505,">="&$F38,'Suivi EPP'!$AF$6:$AF$505,"<="&$G38,'Suivi EPP'!$S$6:$S$505,"<>Sorti") -> 0
E39: =F39 -> 46447 | F39: =EOMONTH(DateRef,5)+1 -> 46447 | G39: =EOMONTH(DateRef,6) -> 46477 | H39: =COUNTIFS('Suivi EPP'!$P$6:$P$505,">="&$F39,'Suivi EPP'!$P$6:$P$505,"<="&$G39,'Suivi EPP'!$S$6:$S$505,"<>Sorti") -> 0 | I39: =COUNTIFS('Suivi EPP'!$Q$6:$Q$505,">="&$F39,'Suivi EPP'!$Q$6:$Q$505,"<="&$G39,'Suivi EPP'!$S$6:$S$505,"<>Sorti") -> 0 | J39: =COUNTIFS('Suivi EPP'!$AF$6:$AF$505,">="&$F39,'Suivi EPP'!$AF$6:$AF$505,"<="&$G39,'Suivi EPP'!$S$6:$S$505,"<>Sorti") -> 0
E40: =F40 -> 46478 | F40: =EOMONTH(DateRef,6)+1 -> 46478 | G40: =EOMONTH(DateRef,7) -> 46507 | H40: =COUNTIFS('Suivi EPP'!$P$6:$P$505,">="&$F40,'Suivi EPP'!$P$6:$P$505,"<="&$G40,'Suivi EPP'!$S$6:$S$505,"<>Sorti") -> 0 | I40: =COUNTIFS('Suivi EPP'!$Q$6:$Q$505,">="&$F40,'Suivi EPP'!$Q$6:$Q$505,"<="&$G40,'Suivi EPP'!$S$6:$S$505,"<>Sorti") -> 0 | J40: =COUNTIFS('Suivi EPP'!$AF$6:$AF$505,">="&$F40,'Suivi EPP'!$AF$6:$AF$505,"<="&$G40,'Suivi EPP'!$S$6:$S$505,"<>Sorti") -> 0
E41: =F41 -> 46508 | F41: =EOMONTH(DateRef,7)+1 -> 46508 | G41: =EOMONTH(DateRef,8) -> 46538 | H41: =COUNTIFS('Suivi EPP'!$P$6:$P$505,">="&$F41,'Suivi EPP'!$P$6:$P$505,"<="&$G41,'Suivi EPP'!$S$6:$S$505,"<>Sorti") -> 0 | I41: =COUNTIFS('Suivi EPP'!$Q$6:$Q$505,">="&$F41,'Suivi EPP'!$Q$6:$Q$505,"<="&$G41,'Suivi EPP'!$S$6:$S$505,"<>Sorti") -> 0 | J41: =COUNTIFS('Suivi EPP'!$AF$6:$AF$505,">="&$F41,'Suivi EPP'!$AF$6:$AF$505,"<="&$G41,'Suivi EPP'!$S$6:$S$505,"<>Sorti") -> 0
...

Sheet Suivi EPP
A1: Suivi des entretiens de parcours professionnel (EPP)
A2: Date de référence : | C2: =DateRef -> 46288 | D2: Article L6315-1 du Code du travail – loi n° 2025-989 du 24/10/2025 (en vigueur depuis le 26/10/2025) : 1er EPP dans l'année suivant l'embauche, puis tous les 4 ans à compter du précédent entretien ; état des lieux récapitulatif tous les 8 ans.
A3: Colonnes jaunes = saisie · Colonnes grises = calcul automatique (ne pas modifier) · Pour tout salarié de plus d'un an, la date du précédent entretien professionnel (colonne L) est indispensable · Lignes EX-… = exemples fictifs à effacer.
A4: IDENTIFICATION DU SALARIÉ | J4: ANCIENNETÉ & PRÉCÉDENT ENTRETIEN | O4: PROCHAIN ENTRETIEN DE PARCOURS PROFESSIONNEL | U4: REPRISE APRÈS ABSENCE | X4: MI-CARRIÈRE | AA4: FIN DE CARRIÈRE | AD4: ÉTAT DES LIEUX RÉCAPITULATIF (8 ANS) | AK4: SUIVI
A5: Matricule | B5: Nom | C5: Prénom | D5: Service | E5: Poste | F5: Responsable de l'entretien | G5: Date de naissance | H5: Date d'embauche | I5: Date de sortie | J5: Ancienneté (années) | K5: Ancienneté | L5: Date du précédent entretien professionnel (saisie) | M5: Dernier entretien consigné au Journal | N5: Dernier entretien retenu | O5: Règle de calcul appliquée | P5: Échéance du prochain EPP | Q5: Date prévue (convocation) | R5: Jours restants | S5: Statut EPP | T5: Alertes / contrôles | U5: Type d'absence | V5: Date de reprise | W5: EPP de reprise | X5: Date de la visite de mi-carrière | Y5: Échéance EPP post-visite | Z5: Statut EPP mi-carrière | AA5: Âge | AB5: Date des 60 ans | AC5: EPP de fin de carrière | AD5: Date du dernier état des lieux / bilan (saisie) | AE5: Début du cycle en cours | AF5: Échéance de l'état des lieux | AG5: Statut état des lieux | AH5: Formation non obligatoire suivie sur le cycle ? | AI5: Tous les EPP dus sur le cycle réalisés ? | AJ5: Risque abondement CPF | AK5: Commentaires
A6: EX-001 | B6: MARTIN | C6: Julie | D6: Commercial | E6: Chargée d'affaires | F6: P. Durand | G6: 32245 | H6: 46055 | J6: =IF(OR($B6="",$H6=""),"",IF($H6>DateRef,0,YEARFRAC($H6,DateRef,1))) -> 0.63835616 | K6: =IF(OR($B6="",$H6=""),"",IF(EDATE($H6,12)<=DateRef,"Plus d'un an","Moins d'un an")) -> Moins d'un an | M6: =IF(OR($B6="",$A6=""),"",IF(SUMPRODUCT(MAX((Journal!$A$6:$A$1005=$A6)*Journal!$C$6:$C$1005))=0,"",SUMPRODUCT(MAX((Journal!$A$6:$A$1005=$A6)*Journal!$C$6:$C$1005)))) | N6: =IF($B6="","",IF(MAX($L6,$M6)=0,"",MAX($L6,$M6))) | O6: =IF(OR($B6="",$H6=""),"",IF($N6="",IF(EDATE($H6,DelaiPremierEPP)>DateRef,"1er EPP (1re année)","Aucun entretien renseigné"),IF(AND(ReglesTransitoires="Oui",EDATE($N6,AnciennePeriodiciteEP*12)<DateVigueur),"Retard antérieur à la réforme","Périodicité "&PeriodiciteEPP&" ans"))) -> 1er EPP (1re année) | P6: =IF(OR($B6="",$H6=""),"",IF($N6="",EDATE($H6,DelaiPremierEPP),IF(AND(ReglesTransitoires="Oui",EDATE($N6,AnciennePeriodiciteEP*12)<DateVigueur),EDATE($N6,AnciennePeriodiciteEP*12),EDATE($N6,PeriodiciteEPP*12)))) -> 46420 | R6: =IF(OR($P6="",AND($I6<>"",$I6<=DateRef)),"",$P6-DateRef) -> 132 | S6: =IF($B6="","",IF(AND($I6<>"",$I6<=DateRef),"Sorti",IF($H6="","À compléter",IF(AND($Q6<>"",$Q6>=DateRef,$Q6<=$P6),"Planifié",IF($R6<0,"En retard",IF($R6<=SeuilAlerteEPP,"À planifier","À jour")))))) -> À jour | T6: =IF(OR($B6="",$S6="Sorti"),"",MID(IF($H6=""," | Date d'embauche manquante","")&IF(AND($K6="Plus d'un an",$N6="")," | Précédent entretien à renseigner (ancienneté > 1 an)","")&IF($O6="Retard antérieur à la réforme"," | Ancien délai de 2 ans expiré avant la réforme","")&IF(AND($N6<>"",$H6<>"",$N6<$H6)," | Entretien antérieur à l'embauche ?","")&IF(AND($N6<>"",$N6>DateRef)," | Entretien daté dans le futur ?","")&IF(AND($Q6<>"",$P6<>"",$Q6>$P6)," | Date prévue après l'échéance","")&IF(AND($Q6<>"",$Q6<DateRef,OR($N6="",$N6<$Q6))," | Entretien prévu passé : le consigner au Journal","")&IF(AND($G6<>"",$X6="",YEAR(DateRef)-YEAR($G6)>=AgeMiCarriere-1,YEAR(DateRef)-YEAR($G6)<=AgeMiCarriere+1)," | Visite de mi-carrière à vérifier",""),4,1000)) | W6: =IF(OR($B6="",$V6=""),"",IF(AND($I6<>"",$I6<=DateRef),"",IF(AND($N6<>"",$N6>=$V6),"Réalisé",IF(AND($N6<>"",$N6>=EDATE($V6,-FenetreRetour)),"Dispensé (EPP récent)",IF($V6>DateRef,"À prévoir à la reprise","À proposer (reprise passée)"))))) | Y6: =IF(OR($B6="",$X6=""),"",EDATE($X6,DelaiMiCarriere)) | Z6: =IF(OR($B6="",$X6=""),"",IF(AND($I6<>"",$I6<=DateRef),"",IF(AND($N6<>"",$N6>=$X6),"Réalisé",IF($Y6<DateRef,"En retard","À planifier")))) | AA6: =IF(OR($B6="",$G6=""),"",IF($G6>DateRef,"",DATEDIF($G6,DateRef,"y"))) -> 38 | AB6: =IF(OR($B6="",$G6=""),"",EDATE($G6,AgeFinCarriere*12)) -> 54160 | AC6: =IF(OR($B6="",$G6="",$H6=""),"",IF(AND($I6<>"",$I6<=DateRef),"",IF($AB6<DateVigueur,"Non concerné",IF(AND($N6<>"",$N6>=MAX(EDATE($AB6,-FenetreFinCarriere*12),DateVigueur),$N6<=$AB6),"Réalisé",IF(DateRef>$AB6,"Non réalisé",IF(AND($Q6<>"",$Q6>=EDATE($AB6,-FenetreFinCarriere*12),$Q6<=$AB6),"Planifié dans la fenêtre",IF(AND(MAX($P6,DateRef)>=EDATE($AB6,-FenetreFinCarriere*12),MAX($P6,DateRef)<=$AB6),"Prochain EPP dans la fenêtre",IF(MAX($P6,DateRef)>$AB6,"À programmer avant 60 ans","")))))))) | AE6: =IF(OR($B6="",$H6="",AND($I6<>"",$I6<=DateRef)),"",MAX($H6,$AD6,IF($A6="",0,SUMPRODUCT(MAX((Journal!$A$6:$A$1005=$A6)*((Journal!$D$6:$D$1005=TypeEDL)+(Journal!$D$6:$D$1005=TypeBilan6))*Journal!$C$6:$C$1005))))) -> 46055 | AF6: =IF($AE6="","",IF(AND(ReglesTransitoires="Oui",EDATE($AE6,AnciennePeriodiciteEDL*12)<DateVigueur),EDATE($AE6,AnciennePeriodiciteEDL*12),EDATE($AE6,PeriodiciteEDL*12))) -> 48977 | AG6: =IF($AF6="","",IF(AND($I6<>"",$I6<=DateRef),"",IF($AF6<DateRef,"En retard",IF($AF6-DateRef<=SeuilAlerteEDL,"À prévoir","À jour")))) -> À jour | AJ6: =IF(OR($B6="",$H6=""),"",IF(AND($I6<>"",$I6<=DateRef),"",IF(Effectif<SeuilEffectif,"Non concerné (< "&SeuilEffectif&" salariés)",IF($AH6="Oui","Pas de risque",IF(AND(OR($AI6="Non",$S6="En retard"),$AH6="Non"),"Risque abondement",IF(OR($AI6="Non",$S6="En retard"),"À vérifier (formation ?)",IF($AI6="Oui","Pas de risque","À compléter"))))))) -> À compléter | AK6: Moins d'un an : 1er EPP dans l'année suivant l'embauche
A7: EX-002 | B7: BERNARD | C7: Thomas | D7: Production | E7: Technicien de maintenance | F7: A. Roux | G7: 29834 | H7: 42170 | J7: =IF(OR($B7="",$H7=""),"",IF($H7>DateRef,0,YEARFRAC($H7,DateRef,1))) -> 11.27447 | K7: =IF(OR($B7="",$H7=""),"",IF(EDATE($H7,12)<=DateRef,"Plus d'un an","Moins d'un an")) -> Plus d'un an | L7: 45726 | M7: =IF(OR($B7="",$A7=""),"",IF(SUMPRODUCT(MAX((Journal!$A$6:$A$1005=$A7)*Journal!$C$6:$C$1005))=0,"",SUMPRODUCT(MAX((Journal!$A$6:$A$1005=$A7)*Journal!$C$6:$C$1005)))) | N7: =IF($B7="","",IF(MAX($L7,$M7)=0,"",MAX($L7,$M7))) -> 45726 | O7: =IF(OR($B7="",$H7=""),"",IF($N7="",IF(EDATE($H7,DelaiPremierEPP)>DateRef,"1er EPP (1re année)","Aucun entretien renseigné"),IF(AND(ReglesTransitoires="Oui",EDATE($N7,AnciennePeriodiciteEP*12)<DateVigueur),"Retard antérieur à la réforme","Périodicité "&PeriodiciteEPP&" ans"))) -> Périodicité 4 ans | P7: =IF(OR($B7="",$H7=""),"",IF($N7="",EDATE($H7,DelaiPremierEPP),IF(AND(ReglesTransitoires="Oui",EDATE($N7,AnciennePeriodiciteEP*12)<DateVigueur),EDATE($N7,AnciennePeriodiciteEP*12),EDATE($N7,PeriodiciteEPP*12)))) -> 47187 | R7: =IF(OR($P7="",AND($I7<>"",$I7<=DateRef)),"",$P7-DateRef) -> 899 | S7: =IF($B7="","",IF(AND($I7<>"",$I7<=DateRef),"Sorti",IF($H7="","À compléter",IF(AND($Q7<>"",$Q7>=DateRef,$Q7<=$P7),"Planifié",IF($R7<0,"En retard",IF($R7<=SeuilAlerteEPP,"À planifier","À jour")))))) -> À jour | T7: =IF(OR($B7="",$S7="Sorti"),"",MID(IF($H7=""," | Date d'embauche manquante","")&IF(AND($K7="Plus d'un an",$N7="")," | Précédent entretien à renseigner (ancienneté > 1 an)","")&IF($O7="Retard antérieur à la réforme"," | Ancien délai de 2 ans expiré avant la réforme","")&IF(AND($N7<>"",$H7<>"",$N7<$H7)," | Entretien antérieur à l'embauche ?","")&IF(AND($N7<>"",$N7>DateRef)," | Entretien daté dans le futur ?","")&IF(AND($Q7<>"",$P7<>"",$Q7>$P7)," | Date prévue après l'échéance","")&IF(AND($Q7<>"",$Q7<DateRef,OR($N7="",$N7<$Q7))," | Entretien prévu passé : le consigner au Journal","")&IF(AND($G7<>"",$X7="",YEAR(DateRef)-YEAR($G7)>=AgeMiCarriere-1,YEAR(DateRef)-YEAR($G7)<=AgeMiCarriere+1)," | Visite de mi-carrière à vérifier",""),4,1000)) | W7: =IF(OR($B7="",$V7=""),"",IF(AND($I7<>"",$I7<=DateRef),"",IF(AND($N7<>"",$N7>=$V7),"Réalisé",IF(AND($N7<>"",$N7>=EDATE($V7,-FenetreRetour)),"Dispensé (EPP récent)",IF($V7>DateRef,"À prévoir à la reprise","À proposer (reprise passée)"))))) | X7: 46267 | Y7: =IF(OR($B7="",$X7=""),"",EDATE($X7,DelaiMiCarriere)) -> 46328 | Z7: =IF(OR($B7="",$X7=""),"",IF(AND($I7<>"",$I7<=DateRef),"",IF(AND($N7<>"",$N7>=$X7),"Réalisé",IF($Y7<DateRef,"En retard","À planifier")))) -> À planifier | AA7: =IF(OR($B7="",$G7=""),"",IF($G7>DateRef,"",DATEDIF($G7,DateRef,"y"))) -> 45 | AB7: =IF(OR($B7="",$G7=""),"",EDATE($G7,AgeFinCarriere*12)) -> 51749 | AC7: =IF(OR($B7="",$G7="",$H7=""),"",IF(AND($I7<>"",$I7<=DateRef),"",IF($AB7<DateVigueur,"Non concerné",IF(AND($N7<>"",$N7>=MAX(EDATE($AB7,-FenetreFinCarriere*12),DateVigueur),$N7<=$AB7),"Réalisé",IF(DateRef>$AB7,"Non réalisé",IF(AND($Q7<>"",$Q7>=EDATE($AB7,-FenetreFinCarriere*12),$Q7<=$AB7),"Planifié dans la fenêtre",IF(AND(MAX($P7,DateRef)>=EDATE($AB7,-FenetreFinCarriere*12),MAX($P7,DateRef)<=$AB7),"Prochain EPP dans la fenêtre",IF(MAX($P7,DateRef)>$AB7,"À programmer avant 60 ans","")))))))) | AD7: 44367 | AE7: =IF(OR($B7="",$H7="",AND($I7<>"",$I7<=DateRef)),"",MAX($H7,$AD7,IF($A7="",0,SUMPRODUCT(MAX((Journal!$A$6:$A$1005=$A7)*((Journal!$D$6:$D$1005=TypeEDL)+(Journal!$D$6:$D$1005=TypeBilan6))*Journal!$C$6:$C$1005))))) -> 44367 | AF7: =IF($AE7="","",IF(AND(ReglesTransitoires="Oui",EDATE($AE7,AnciennePeriodiciteEDL*12)<DateVigueur),EDATE($AE7,AnciennePeriodiciteEDL*12),EDATE($AE7,PeriodiciteEDL*12))) -> 47289 | AG7: =IF($AF7="","",IF(AND($I7<>"",$I7<=DateRef),"",IF($AF7<DateRef,"En retard",IF($AF7-DateRef<=SeuilAlerteEDL,"À prévoir","À jour")))) -> À jour | AH7: Oui | AI7: Oui | AJ7: =IF(OR($B7="",$H7=""),"",IF(AND($I7<>"",$I7<=DateRef),"",IF(Effectif<SeuilEffectif,"Non concerné (< "&SeuilEffectif&" salariés)",IF($AH7="Oui","Pas de risque",IF(AND(OR($AI7="Non",$S7="En retard"),$AH7="Non"),"Risque abondement",IF(OR($AI7="Non",$S7="En retard"),"À vérifier (formation ?)",IF($AI7="Oui","Pas de risque","À compléter"))))))) -> Pas de risque | AK7: Visite de mi-carrière récente : EPP sous 2 mois
A8: EX-003 | B8: PETIT | C8: Sophie | D8: Ressources humaines | E8: Gestionnaire paie | F8: M. Leroy | G8: 33199 | H8: 43709 | J8: =IF(OR($B8="",$H8=""),"",IF($H8>DateRef,0,YEARFRAC($H8,DateRef,1))) -> 7.0609172 | K8: =IF(OR($B8="",$H8=""),"",IF(EDATE($H8,12)<=DateRef,"Plus d'un an","Moins d'un an")) -> Plus d'un an | L8: 45066 | M8: =IF(OR($B8="",$A8=""),"",IF(SUMPRODUCT(MAX((Journal!$A$6:$A$1005=$A8)*Journal!$C$6:$C$1005))=0,"",SUMPRODUCT(MAX((Journal!$A$6:$A$1005=$A8)*Journal!$C$6:$C$1005)))) | N8: =IF($B8="","",IF(MAX($L8,$M8)=0,"",MAX($L8,$M8))) -> 45066 | O8: =IF(OR($B8="",$H8=""),"",IF($N8="",IF(EDATE($H8,DelaiPremierEPP)>DateRef,"1er EPP (1re année)","Aucun entretien renseigné"),IF(AND(ReglesTransitoires="Oui",EDATE($N8,AnciennePeriodiciteEP*12)<DateVigueur),"Retard antérieur à la réforme","Périodicité "&PeriodiciteEPP&" ans"))) -> Retard antérieur à la réforme | P8: =IF(OR($B8="",$H8=""),"",IF($N8="",EDATE($H8,DelaiPremierEPP),IF(AND(ReglesTransitoires="Oui",EDATE($N8,AnciennePeriodiciteEP*12)<DateVigueur),EDATE($N8,AnciennePeriodiciteEP*12),EDATE($N8,PeriodiciteEPP*12)))) -> 45797 | R8: =IF(OR($P8="",AND($I8<>"",$I8<=DateRef)),"",$P8-DateRef) -> -491 | S8: =IF($B8="","",IF(AND($I8<>"",$I8<=DateRef),"Sorti",IF($H8="","À compléter",IF(AND($Q8<>"",$Q8>=DateRef,$Q8<=$P8),"Planifié",IF($R8<0,"En retard",IF($R8<=SeuilAlerteEPP,"À planifier","À jour")))))) -> En retard | T8: =IF(OR($B8="",$S8="Sorti"),"",MID(IF($H8=""," | Date d'embauche manquante","")&IF(AND($K8="Plus d'un an",$N8="")," | Précédent entretien à renseigner (ancienneté > 1 an)","")&IF($O8="Retard antérieur à la réforme"," | Ancien délai de 2 ans expiré avant la réforme","")&IF(AND($N8<>"",$H8<>"",$N8<$H8)," | Entretien antérieur à l'embauche ?","")&IF(AND($N8<>"",$N8>DateRef)," | Entretien daté dans le futur ?","")&IF(AND($Q8<>"",$P8<>"",$Q8>$P8)," | Date prévue après l'échéance","")&IF(AND($Q8<>"",$Q8<DateRef,OR($N8="",$N8<$Q8))," | Entretien prévu passé : le consigner au Journal","")&IF(AND($G8<>"",$X8="",YEAR(DateRef)-YEAR($G8)>=AgeMiCarriere-1,YEAR(DateRef)-YEAR($G8)<=AgeMiCarriere+1)," | Visite de mi-carrière à vérifier",""),4,1000)) -> Ancien délai de 2 ans expiré avant la réforme | U8: Congé parental d'éducation | V8: 46300 | W8: =IF(OR($B8="",$V8=""),"",IF(AND($I8<>"",$I8<=DateRef),"",IF(AND($N8<>"",$N8>=$V8),"Réalisé",IF(AND($N8<>"",$N8>=EDATE($V8,-FenetreRetour)),"Dispensé (EPP récent)",IF($V8>DateRef,"À prévoir à la reprise","À proposer (reprise passée)"))))) -> À prévoir à la reprise | Y8: =IF(OR($B8="",$X8=""),"",EDATE($X8,DelaiMiCarriere)) | Z8: =IF(OR($B8="",$X8=""),"",IF(AND($I8<>"",$I8<=DateRef),"",IF(AND($N8<>"",$N8>=$X8),"Réalisé",IF($Y8<DateRef,"En retard","À planifier")))) | AA8: =IF(OR($B8="",$G8=""),"",IF($G8>DateRef,"",DATEDIF($G8,DateRef,"y"))) -> 35 | AB8: =IF(OR($B8="",$G8=""),"",EDATE($G8,AgeFinCarriere*12)) -> 55114 | AC8: =IF(OR($B8="",$G8="",$H8=""),"",IF(AND($I8<>"",$I8<=DateRef),"",IF($AB8<DateVigueur,"Non concerné",IF(AND($N8<>"",$N8>=MAX(EDATE($AB8,-FenetreFinCarriere*12),DateVigueur),$N8<=$AB8),"Réalisé",IF(DateRef>$AB8,"Non réalisé",IF(AND($Q8<>"",$Q8>=EDATE($AB8,-FenetreFinCarriere*12),$Q8<=$AB8),"Planifié dans la fenêtre",IF(AND(MAX($P8,DateRef)>=EDATE($AB8,-FenetreFinCarriere*12),MAX($P8,DateRef)<=$AB8),"Prochain EPP dans la fenêtre",IF(MAX($P8,DateRef)>$AB8,"À programmer avant 60 ans","")))))))) | AE8: =IF(OR($B8="",$H8="",AND($I8<>"",$I8<=DateRef)),"",MAX($H8,$AD8,IF($A8="",0,SUMPRODUCT(MAX((Journal!$A$6:$A$1005=$A8)*((Journal!$D$6:$D$1005=TypeEDL)+(Journal!$D$6:$D$1005=TypeBilan6))*Journal!$C$6:$C$1005))))) -> 43709 | AF8: =IF($AE8="","",IF(AND(ReglesTransitoires="Oui",EDATE($AE8,AnciennePeriodiciteEDL*12)<DateVigueur),EDATE($AE8,AnciennePeriodiciteEDL*12),EDATE($AE8,PeriodiciteEDL*12))) -> 45901 | AG8: =IF($AF8="","",IF(AND($I8<>"",$I8<=DateRef),"",IF($AF8<DateRef,"En retard",IF($AF8-DateRef<=SeuilAlerteEDL,"À prévoir","À jour")))) -> En retard | AH8: Oui | AJ8: =IF(OR($B8="",$H8=""),"",IF(AND($I8<>"",$I8<=DateRef),"",IF(Effectif<SeuilEffectif,"Non concerné (< "&SeuilEffectif&" salariés)",IF($AH8="Oui","Pas de risque",IF(AND(OR($AI8="Non",$S8="En retard"),$AH8="Non"),"Risque abondement",IF(OR($AI8="Non",$S8="En retard"),"À vérifier (formation ?)",IF($AI8="Oui","Pas de risque","À compléter"))))))) -> Pas de risque | AK8: Délai de 2 ans expiré avant la réforme + reprise à venir
A9: EX-004 | B9: ROBERT | C9: Karim | D9: Logistique | E9: Cariste | F9: A. Roux | G9: 24545 | H9: 39457 | J9: =IF(OR($B9="",$H9=""),"",IF($H9>DateRef,0,YEARFRAC($H9,DateRef,1))) -> 18.701585 | K9: =IF(OR($B9="",$H9=""),"",IF(EDATE($H9,12)<=DateRef,"Plus d'un an","Moins d'un an")) -> Plus d'un an | L9: 45641 | M9: =IF(OR($B9="",$A9=""),"",IF(SUMPRODUCT(MAX((Journal!$A$6:$A$1005=$A9)*Journal!$C$6:$C$1005))=0,"",SUMPRODUCT(MAX((Journal!$A$6:$A$1005=$A9)*Journal!$C$6:$C$1005)))) | N9: =IF($B9="","",IF(MAX($L9,$M9)=0,"",MAX($L9,$M9))) -> 45641 | O9: =IF(OR($B9="",$H9=""),"",IF($N9="",IF(EDATE($H9,DelaiPremierEPP)>DateRef,"1er EPP (1re année)","Aucun entretien renseigné"),IF(AND(ReglesTransitoires="Oui",EDATE($N9,AnciennePeriodiciteEP*12)<DateVigueur),"Retard antérieur à la réforme","Périodicité "&PeriodiciteEPP&" ans"))) -> Périodicité 4 ans | P9: =IF(OR($B9="",$H9=""),"",IF($N9="",EDATE($H9,DelaiPremierEPP),IF(AND(ReglesTransitoires="Oui",EDATE($N9,AnciennePeriodiciteEP*12)<DateVigueur),EDATE($N9,AnciennePeriodiciteEP*12),EDATE($N9,PeriodiciteEPP*12)))) -> 47102 | R9: =IF(OR($P9="",AND($I9<>"",$I9<=DateRef)),"",$P9-DateRef) -> 814 | S9: =IF($B9="","",IF(AND($I9<>"",$I9<=DateRef),"Sorti",IF($H9="","À compléter",IF(AND($Q9<>"",$Q9>=DateRef,$Q9<=$P9),"Planifié",IF($R9<0,"En retard",IF($R9<=SeuilAlerteEPP,"À planifier","À jour")))))) -> À jour | T9: =IF(OR($B9="",$S9="Sorti"),"",MID(IF($H9=""," | Date d'embauche manquante","")&IF(AND($K9="Plus d'un an",$N9="")," | Précédent entretien à renseigner (ancienneté > 1 an)","")&IF($O9="Retard antérieur à la réforme"," | Ancien délai de 2 ans expiré avant la réforme","")&IF(AND($N9<>"",$H9<>"",$N9<$H9)," | Entretien antérieur à l'embauche ?","")&IF(AND($N9<>"",$N9>DateRef)," | Entretien daté dans le futur ?","")&IF(AND($Q9<>"",$P9<>"",$Q9>$P9)," | Date prévue après l'échéance","")&IF(AND($Q9<>"",$Q9<DateRef,OR($N9="",$N9<$Q9))," | Entretien prévu passé : le consigner au Journal","")&IF(AND($G9<>"",$X9="",YEAR(DateRef)-YEAR($G9)>=AgeMiCarriere-1,YEAR(DateRef)-YEAR($G9)<=AgeMiCarriere+1)," | Visite de mi-carrière à vérifier",""),4,1000)) | W9: =IF(OR($B9="",$V9=""),"",IF(AND($I9<>"",$I9<=DateRef),"",IF(AND($N9<>"",$N9>=$V9),"Réalisé",IF(AND($N9<>"",$N9>=EDATE($V9,-FenetreRetour)),"Dispensé (EPP récent)",IF($V9>DateRef,"À prévoir à la reprise","À proposer (reprise passée)"))))) | Y9: =IF(OR($B9="",$X9=""),"",EDATE($X9,DelaiMiCarriere)) | Z9: =IF(OR($B9="",$X9=""),"",IF(AND($I9<>"",$I9<=DateRef),"",IF(AND($N9<>"",$N9>=$X9),"Réalisé",IF($Y9<DateRef,"En retard","À planifier")))) | AA9: =IF(OR($B9="",$G9=""),"",IF($G9>DateRef,"",DATEDIF($G9,DateRef,"y"))) -> 59 | AB9: =IF(OR($B9="",$G9=""),"",EDATE($G9,AgeFinCarriere*12)) -> 46460 | AC9: =IF(OR($B9="",$G9="",$H9=""),"",IF(AND($I9<>"",$I9<=DateRef),"",IF($AB9<DateVigueur,"Non concerné",IF(AND($N9<>"",$N9>=MAX(EDATE($AB9,-FenetreFinCarriere*12),DateVigueur),$N9<=$AB9),"Réalisé",IF(DateRef>$AB9,"Non réalisé",IF(AND($Q9<>"",$Q9>=EDATE($AB9,-FenetreFinCarriere*12),$Q9<=$AB9),"Planifié dans la fenêtre",IF(AND(MAX($P9,DateRef)>=EDATE($AB9,-FenetreFinCarriere*12),MAX($P9,DateRef)<=$AB9),"Prochain EPP dans la fenêtre",IF(MAX($P9,DateRef)>$AB9,"À programmer avant 60 ans","")))))))) -> À programmer avant 60 ans | AD9: 43842 | AE9: =IF(OR($B9="",$H9="",AND($I9<>"",$I9<=DateRef)),"",MAX($H9,$AD9,IF($A9="",0,SUMPRODUCT(MAX((Journal!$A$6:$A$1005=$A9)*((Journal!$D$6:$D$1005=TypeEDL)+(Journal!$D$6:$D$1005=TypeBilan6))*Journal!$C$6:$C$1005))))) -> 43842 | AF9: =IF($AE9="","",IF(AND(ReglesTransitoires="Oui",EDATE($AE9,AnciennePeriodiciteEDL*12)<DateVigueur),EDATE($AE9,AnciennePeriodiciteEDL*12),EDATE($AE9,PeriodiciteEDL*12))) -> 46764 | AG9: =IF($AF9="","",IF(AND($I9<>"",$I9<=DateRef),"",IF($AF9<DateRef,"En retard",IF($AF9-DateRef<=SeuilAlerteEDL,"À prévoir","À jour")))) -> À jour | AH9: Oui | AI9: Oui | AJ9: =IF(OR($B9="",$H9=""),"",IF(AND($I9<>"",$I9<=DateRef),"",IF(Effectif<SeuilEffectif,"Non concerné (< "&SeuilEffectif&" salariés)",IF($AH9="Oui","Pas de risque",IF(AND(OR($AI9="Non",$S9="En retard"),$AH9="Non"),"Risque abondement",IF(OR($AI9="Non",$S9="En retard"),"À vérifier (formation ?)",IF($AI9="Oui","Pas de risque","À compléter"))))))) -> Pas de risque | AK9: 60 ans en mars 2027 : prochain EPP à avancer
A10: EX-005 | B10: RICHARD | C10: Camille | D10: Informatique | E10: Développeuse | F10: L. Garnier | G10: 34910 | H10: 44256 | J10: =IF(OR($B10="",$H10=""),"",IF($H10>DateRef,0,YEARFRAC($H10,DateRef,1))) -> 5.5645824 | K10: =IF(OR($B10="",$H10=""),"",IF(EDATE($H10,12)<=DateRef,"Plus d'un an","Moins d'un an")) -> Plus d'un an | M10: =IF(OR($B10="",$A10=""),"",IF(SUMPRODUCT(MAX((Journal!$A$6:$A$1005=$A10)*Journal!$C$6:$C$1005))=0,"",SUMPRODUCT(MAX((Journal!$A$6:$A$1005=$A10)*Journal!$C$6:$C$1005)))) | N10: =IF($B10="","",IF(MAX($L10,$M10)=0,"",MAX($L10,$M10))) | O10: =IF(OR($B10="",$H10=""),"",IF($N10="",IF(EDATE($H10,DelaiPremierEPP)>DateRef,"1er EPP (1re année)","Aucun entretien renseigné"),IF(AND(ReglesTransitoires="Oui",EDATE($N10,AnciennePeriodiciteEP*12)<DateVigueur),"Retard antérieur à la réforme","Périodicité "&PeriodiciteEPP&" ans"))) -> Aucun entretien renseigné | P10: =IF(OR($B10="",$H10=""),"",IF($N10="",EDATE($H10,DelaiPremierEPP),IF(AND(ReglesTransitoires="Oui",EDATE($N10,AnciennePeriodiciteEP*12)<DateVigueur),EDATE($N10,AnciennePeriodiciteEP*12),EDATE($N10,PeriodiciteEPP*12)))) -> 44621 | R10: =IF(OR($P10="",AND($I10<>"",$I10<=DateRef)),"",$P10-DateRef) -> -1667 | S10: =IF($B10="","",IF(AND($I10<>"",$I10<=DateRef),"Sorti",IF($H10="","À compléter",IF(AND($Q10<>"",$Q10>=DateRef,$Q10<=$P10),"Planifié",IF($R10<0,"En retard",IF($R10<=SeuilAlerteEPP,"À planifier","À jour")))))) -> En retard | T10: =IF(OR($B10="",$S10="Sorti"),"",MID(IF($H10=""," | Date d'embauche manquante","")&IF(AND($K10="Plus d'un an",$N10="")," | Précédent entretien à renseigner (ancienneté > 1 an)","")&IF($O10="Retard antérieur à la réforme"," | Ancien délai de 2 ans expiré avant la réforme","")&IF(AND($N10<>"",$H10<>"",$N10<$H10)," | Entretien antérieur à l'embauche ?","")&IF(AND($N10<>"",$N10>DateRef)," | Entretien daté dans le futur ?","")&IF(AND($Q10<>"",$P10<>"",$Q10>$P10)," | Date prévue après l'échéance","")&IF(AND($Q10<>"",$Q10<DateRef,OR($N10="",$N10<$Q10))," | Entretien prévu passé : le consigner au Journal","")&IF(AND($G10<>"",$X10="",YEAR(DateRef)-YEAR($G10)>=AgeMiCarriere-1,YEAR(DateRef)-YEAR($G10)<=AgeMiCarriere+1)," | Visite de mi-carrière à vérifier",""),4,1000)) -> Précédent entretien à renseigner (ancienneté > 1 an) | W10: =IF(OR($B10="",$V10=""),"",IF(AND($I10<>"",$I10<=DateRef),"",IF(AND($N10<>"",$N10>=$V10),"Réalisé",IF(AND($N10<>"",$N10>=EDATE($V10,-FenetreRetour)),"Dispensé (EPP récent)",IF($V10>DateRef,"À prévoir à la reprise","À proposer (reprise passée)"))))) | Y10: =IF(OR($B10="",$X10=""),"",EDATE($X10,DelaiMiCarriere)) | Z10: =IF(OR($B10="",$X10=""),"",IF(AND($I10<>"",$I10<=DateRef),"",IF(AND($N10<>"",$N10>=$X10),"Réalisé",IF($Y10<DateRef,"En retard","À planifier")))) | AA10: =IF(OR($B10="",$G10=""),"",IF($G10>DateRef,"",DATEDIF($G10,DateRef,"y"))) -> 31 | AB10: =IF(OR($B10="",$G10=""),"",EDATE($G10,AgeFinCarriere*12)) -> 56825 | AC10: =IF(OR($B10="",$G10="",$H10=""),"",IF(AND($I10<>"",$I10<=DateRef),"",IF($AB10<DateVigueur,"Non concerné",IF(AND($N10<>"",$N10>=MAX(EDATE($AB10,-FenetreFinCarriere*12),DateVigueur),$N10<=$AB10),"Réalisé",IF(DateRef>$AB10,"Non réalisé",IF(AND($Q10<>"",$Q10>=EDATE($AB10,-FenetreFinCarriere*12),$Q10<=$AB10),"Planifié dans la fenêtre",IF(AND(MAX($P10,DateRef)>=EDATE($AB10,-FenetreFinCarriere*12),MAX($P10,DateRef)<=$AB10),"Prochain EPP dans la fenêtre",IF(MAX($P10,DateRef)>$AB10,"À programmer avant 60 ans","")))))))) | AE10: =IF(OR($B10="",$H10="",AND($I10<>"",$I10<=DateRef)),"",MAX($H10,$AD10,IF($A10="",0,SUMPRODUCT(MAX((Journal!$A$6:$A$1005=$A10)*((Journal!$D$6:$D$1005=TypeEDL)+(Journal!$D$6:$D$1005=TypeBilan6))*Journal!$C$6:$C$1005))))) -> 44256 | AF10: =IF($AE10="","",IF(AND(ReglesTransitoires="Oui",EDATE($AE10,AnciennePeriodiciteEDL*12)<DateVigueur),EDATE($AE10,AnciennePeriodiciteEDL*12),EDATE($AE10,PeriodiciteEDL*12))) -> 47178 | AG10: =IF($AF10="","",IF(AND($I10<>"",$I10<=DateRef),"",IF($AF10<DateRef,"En retard",IF($AF10-DateRef<=SeuilAlerteEDL,"À prévoir","À jour")))) -> À jour | AJ10: =IF(OR($B10="",$H10=""),"",IF(AND($I10<>"",$I10<=DateRef),"",IF(Effectif<SeuilEffectif,"Non concerné (< "&SeuilEffectif&" salariés)",IF($AH10="Oui","Pas de risque",IF(AND(OR($AI10="Non",$S10="En retard"),$AH10="Non"),"Risque abondement",IF(OR($AI10="Non",$S10="En retard"),"À vérifier (formation ?)",IF($AI10="Oui","Pas de risque","À compléter"))))))) -> À vérifier (formation ?) | AK10: Plus d'un an sans date de précédent entretien
A11: EX-006 | B11: DURAND | C11: Nicolas | D11: Administratif et finance | E11: Comptable | F11: M. Leroy | G11: 28894 | H11: 42829 | J11: =IF(OR($B11="",$H11=""),"",IF($H11>DateRef,0,YEARFRAC($H11,DateRef,1))) -> 9.4715225 | K11: =IF(OR($B11="",$H11=""),"",IF(EDATE($H11,12)<=DateRef,"Plus d'un an","Moins d'un an")) -> Plus d'un an | L11: 45577 | M11: =IF(OR($B11="",$A11=""),"",IF(SUMPRODUCT(MAX((Journal!$A$6:$A$1005=$A11)*Journal!$C$6:$C$1005))=0,"",SUMPRODUCT(MAX((Journal!$A$6:$A$1005=$A11)*Journal!$C$6:$C$1005)))) | N11: =IF($B11="","",IF(MAX($L11,$M11)=0,"",MAX($L11,$M11))) -> 45577 | O11: =IF(OR($B11="",$H11=""),"",IF($N11="",IF(EDATE($H11,DelaiPremierEPP)>DateRef,"1er EPP (1re année)","Aucun entretien renseigné"),IF(AND(ReglesTransitoires="Oui",EDATE($N11,AnciennePeriodiciteEP*12)<DateVigueur),"Retard antérieur à la réforme","Périodicité "&PeriodiciteEPP&" ans"))) -> Périodicité 4 ans | P11: =IF(OR($B11="",$H11=""),"",IF($N11="",EDATE($H11,DelaiPremierEPP),IF(AND(ReglesTransitoires="Oui",EDATE($N11,AnciennePeriodiciteEP*12)<DateVigueur),EDATE($N11,AnciennePeriodiciteEP*12),EDATE($N11,PeriodiciteEPP*12)))) -> 47038 | R11: =IF(OR($P11="",AND($I11<>"",$I11<=DateRef)),"",$P11-DateRef) -> 750 | S11: =IF($B11="","",IF(AND($I11<>"",$I11<=DateRef),"Sorti",IF($H11="","À compléter",IF(AND($Q11<>"",$Q11>=DateRef,$Q11<=$P11),"Planifié",IF($R11<0,"En retard",IF($R11<=SeuilAlerteEPP,"À planifier","À jour")))))) -> À jour | T11: =IF(OR($B11="",$S11="Sorti"),"",MID(IF($H11=""," | Date d'embauche manquante","")&IF(AND($K11="Plus d'un an",$N11="")," | Précédent entretien à renseigner (ancienneté > 1 an)","")&IF($O11="Retard antérieur à la réforme"," | Ancien délai de 2 ans expiré avant la réforme","")&IF(AND($N11<>"",$H11<>"",$N11<$H11)," | Entretien antérieur à l'embauche ?","")&IF(AND($N11<>"",$N11>DateRef)," | Entretien daté dans le futur ?","")&IF(AND($Q11<>"",$P11<>"",$Q11>$P11)," | Date prévue après l'échéance","")&IF(AND($Q11<>"",$Q11<DateRef,OR($N11="",$N11<$Q11))," | Entretien prévu passé : le consigner au Journal","")&IF(AND($G11<>"",$X11="",YEAR(DateRef)-YEAR($G11)>=AgeMiCarriere-1,YEAR(DateRef)-YEAR($G11)<=AgeMiCarriere+1)," | Visite de mi-carrière à vérifier",""),4,1000)) | W11: =IF(OR($B11="",$V11=""),"",IF(AND($I11<>"",$I11<=DateRef),"",IF(AND($N11<>"",$N11>=$V11),"Réalisé",IF(AND($N11<>"",$N11>=EDATE($V11,-FenetreRetour)),"Dispensé (EPP récent)",IF($V11>DateRef,"À prévoir à la reprise","À proposer (reprise passée)"))))) | Y11: =IF(OR($B11="",$X11=""),"",EDATE($X11,DelaiMiCarriere)) | Z11: =IF(OR($B11="",$X11=""),"",IF(AND($I11<>"",$I11<=DateRef),"",IF(AND($N11<>"",$N11>=$X11),"Réalisé",IF($Y11<DateRef,"En retard","À planifier")))) | AA11: =IF(OR($B11="",$G11=""),"",IF($G11>DateRef,"",DATEDIF($G11,DateRef,"y"))) -> 47 | AB11: =IF(OR($B11="",$G11=""),"",EDATE($G11,AgeFinCarriere*12)) -> 50809 | AC11: =IF(OR($B11="",$G11="",$H11=""),"",IF(AND($I11<>"",$I11<=DateRef),"",IF($AB11<DateVigueur,"Non concerné",IF(AND($N11<>"",$N11>=MAX(EDATE($AB11,-FenetreFinCarriere*12),DateVigueur),$N11<=$AB11),"Réalisé",IF(DateRef>$AB11,"Non réalisé",IF(AND($Q11<>"",$Q11>=EDATE($AB11,-FenetreFinCarriere*12),$Q11<=$AB11),"Planifié dans la fenêtre",IF(AND(MAX($P11,DateRef)>=EDATE($AB11,-FenetreFinCarriere*12),MAX($P11,DateRef)<=$AB11),"Prochain EPP dans la fenêtre",IF(MAX($P11,DateRef)>$AB11,"À programmer avant 60 ans","")))))))) | AE11: =IF(OR($B11="",$H11="",AND($I11<>"",$I11<=DateRef)),"",MAX($H11,$AD11,IF($A11="",0,SUMPRODUCT(MAX((Journal!$A$6:$A$1005=$A11)*((Journal!$D$6:$D$1005=TypeEDL)+(Journal!$D$6:$D$1005=TypeBilan6))*Journal!$C$6:$C$1005))))) -> 42829 | AF11: =IF($AE11="","",IF(AND(ReglesTransitoires="Oui",EDATE($AE11,AnciennePeriodiciteEDL*12)<DateVigueur),EDATE($AE11,AnciennePeriodiciteEDL*12),EDATE($AE11,PeriodiciteEDL*12))) -> 45020 | AG11: =IF($AF11="","",IF(AND($I11<>"",$I11<=DateRef),"",IF($AF11<DateRef,"En retard",IF($AF11-DateRef<=SeuilAlerteEDL,"À prévoir","À jour")))) -> En retard | AH11: Non | AI11: Non | AJ11: =IF(OR($B11="",$H11=""),"",IF(AND($I11<>"",$I11<=DateRef),"",IF(Effectif<SeuilEffectif,"Non concerné (< "&SeuilEffectif&" salariés)",IF($AH11="Oui","Pas de risque",IF(AND(OR($AI11="Non",$S11="En retard"),$AH11="Non"),"Risque abondement",IF(OR($AI11="Non",$S11="En retard"),"À vérifier (formation ?)",IF($AI11="Oui","Pas de risque","À compléter"))))))) -> Risque abondement | AK11: Bilan à 6 ans non réalisé, aucune formation non obligatoire
A12: EX-007 | B12: MOREAU | C12: Léa | D12: Commercial | E12: Assistante commerciale | F12: P. Durand | G12: 33772 | H12: 45964 | J12: =IF(OR($B12="",$H12=""),"",IF($H12>DateRef,0,YEARFRAC($H12,DateRef,1))) -> 0.88767123 | K12: =IF(OR($B12="",$H12=""),"",IF(EDATE($H12,12)<=DateRef,"Plus d'un an","Moins d'un an")) -> Moins d'un an | M12: =IF(OR($B12="",$A12=""),"",IF(SUMPRODUCT(MAX((Journal!$A$6:$A$1005=$A12)*Journal!$C$6:$C$1005))=0,"",SUMPRODUCT(MAX((Journal!$A$6:$A$1005=$A12)*Journal!$C$6:$C$1005)))) | N12: =IF($B12="","",IF(MAX($L12,$M12)=0,"",MAX($L12,$M12))) | O12: =IF(OR($B12="",$H12=""),"",IF($N12="",IF(EDATE($H12,DelaiPremierEPP)>DateRef,"1er EPP (1re année)","Aucun entretien renseigné"),IF(AND(ReglesTransitoires="Oui",EDATE($N12,AnciennePeriodiciteEP*12)<DateVigueur),"Retard antérieur à la réforme","Périodicité "&PeriodiciteEPP&" ans"))) -> 1er EPP (1re année) | P12: =IF(OR($B12="",$H12=""),"",IF($N12="",EDATE($H12,DelaiPremierEPP),IF(AND(ReglesTransitoires="Oui",EDATE($N12,AnciennePeriodiciteEP*12)<DateVigueur),EDATE($N12,AnciennePeriodiciteEP*12),EDATE($N12,PeriodiciteEPP*12)))) -> 46329 | Q12: 46310 | R12: =IF(OR($P12="",AND($I12<>"",$I12<=DateRef)),"",$P12-DateRef) -> 41 | S12: =IF($B12="","",IF(AND($I12<>"",$I12<=DateRef),"Sorti",IF($H12="","À compléter",IF(AND($Q12<>"",$Q12>=DateRef,$Q12<=$P12),"Planifié",IF($R12<0,"En retard",IF($R12<=SeuilAlerteEPP,"À planifier","À jour")))))) -> Planifié | T12: =IF(OR($B12="",$S12="Sorti"),"",MID(IF($H12=""," | Date d'embauche manquante","")&IF(AND($K12="Plus d'un an",$N12="")," | Précédent entretien à renseigner (ancienneté > 1 an)","")&IF($O12="Retard antérieur à la réforme"," | Ancien délai de 2 ans expiré avant la réforme","")&IF(AND($N12<>"",$H12<>"",$N12<$H12)," | Entretien antérieur à l'embauche ?","")&IF(AND($N12<>"",$N12>DateRef)," | Entretien daté dans le futur ?","")&IF(AND($Q12<>"",$P12<>"",$Q12>$P12)," | Date prévue après l'échéance","")&IF(AND($Q12<>"",$Q12<DateRef,OR($N12="",$N12<$Q12))," | Entretien prévu passé : le consigner au Journal","")&IF(AND($G12<>"",$X12="",YEAR(DateRef)-YEAR($G12)>=AgeMiCarriere-1,YEAR(DateRef)-YEAR($G12)<=AgeMiCarriere+1)," | Visite de mi-carrière à vérifier",""),4,1000)) | W12: =IF(OR($B12="",$V12=""),"",IF(AND($I12<>"",$I12<=DateRef),"",IF(AND($N12<>"",$N12>=$V12),"Réalisé",IF(AND($N12<>"",$N12>=EDATE($V12,-FenetreRetour)),"Dispensé (EPP récent)",IF($V12>DateRef,"À prévoir à la reprise","À proposer (reprise passée)"))))) | Y12: =IF(OR($B12="",$X12=""),"",EDATE($X12,DelaiMiCarriere)) | Z12: =IF(OR($B12="",$X12=""),"",IF(AND($I12<>"",$I12<=DateRef),"",IF(AND($N12<>"",$N12>=$X12),"Réalisé",IF($Y12<DateRef,"En retard","À planifier")))) | AA12: =IF(OR($B12="",$G12=""),"",IF($G12>DateRef,"",DATEDIF($G12,DateRef,"y"))) -> 34 | AB12: =IF(OR($B12="",$G12=""),"",EDATE($G12,AgeFinCarriere*12)) -> 55687 | AC12: =IF(OR($B12="",$G12="",$H12=""),"",IF(AND($I12<>"",$I12<=DateRef),"",IF($AB12<DateVigueur,"Non concerné",IF(AND($N12<>"",$N12>=MAX(EDATE($AB12,-FenetreFinCarriere*12),DateVigueur),$N12<=$AB12),"Réalisé",IF(DateRef>$AB12,"Non réalisé",IF(AND($Q12<>"",$Q12>=EDATE($AB12,-FenetreFinCarriere*12),$Q12<=$AB12),"Planifié dans la fenêtre",IF(AND(MAX($P12,DateRef)>=EDATE($AB12,-FenetreFinCarriere*12),MAX($P12,DateRef)<=$AB12),"Prochain EPP dans la fenêtre",IF(MAX($P12,DateRef)>$AB12,"À programmer avant 60 ans","")))))))) | AE12: =IF(OR($B12="",$H12="",AND($I12<>"",$I12<=DateRef)),"",MAX($H12,$AD12,IF($A12="",0,SUMPRODUCT(MAX((Journal!$A$6:$A$1005=$A12)*((Journal!$D$6:$D$1005=TypeEDL)+(Journal!$D$6:$D$1005=TypeBilan6))*Journal!$C$6:$C$1005))))) -> 45964 | AF12: =IF($AE12="","",IF(AND(ReglesTransitoires="Oui",EDATE($AE12,AnciennePeriodiciteEDL*12)<DateVigueur),EDATE($AE12,AnciennePeriodiciteEDL*12),EDATE($AE12,PeriodiciteEDL*12))) -> 48886 | AG12: =IF($AF12="","",IF(AND($I12<>"",$I12<=DateRef),"",IF($AF12<DateRef,"En retard",IF($AF12-DateRef<=SeuilAlerteEDL,"À prévoir","À jour")))) -> À jour | AJ12: =IF(OR($B12="",$H12=""),"",IF(AND($I12<>"",$I12<=DateRef),"",IF(Effectif<SeuilEffectif,"Non concerné (< "&SeuilEffectif&" salariés)",IF($AH12="Oui","Pas de risque",IF(AND(OR($AI12="Non",$S12="En retard"),$AH12="Non"),"Risque abondement",IF(OR($AI12="Non",$S12="En retard"),"À vérifier (formation ?)",IF($AI12="Oui","Pas de risque","À compléter"))))))) -> À compléter | AK12: 1er EPP convoqué
