Workbook
Name NomCabinet: 'Paramètres'!$C$5
Name AdresseCabinet: 'Paramètres'!$C$6
Name TelCabinet: 'Paramètres'!$C$7
Name EmailRH: 'Paramètres'!$C$8
Name SiteWeb: 'Paramètres'!$C$9
Name Signataire: 'Paramètres'!$C$10
Name FonctionSignataire: 'Paramètres'!$C$11
Name VilleCabinet: 'Paramètres'!$C$13
Name SignatureEmail: 'Paramètres'!$C$12
Name ModeEnvoi: 'Paramètres'!$C$16
Name DossierCandidats: 'Paramètres'!$C$17
Name DossierModeles: 'Paramètres'!$C$18
Name DossierOutlook: 'Paramètres'!$C$19
Name GenererPDF: 'Paramètres'!$C$20
Name SeuilAccuse: 'Paramètres'!$C$23
Name SeuilRelance: 'Paramètres'!$C$24
Name DureeConservation: 'Paramètres'!$C$25
Name Aujourdhui: 'Paramètres'!$C$26
Name Civilites: 'Paramètres'!$B$32:$B$33
Name Postes: 'Paramètres'!$C$32:$C$41
Name Sources: 'Paramètres'!$D$32:$D$41
Name StatutListe: 'Paramètres'!$E$32:$E$41
Name StatutClos: 'Paramètres'!$F$32:$F$41
Name Responsables: 'Paramètres'!$G$32:$G$37
Name Evaluations: 'Paramètres'!$H$32:$H$36
Name Decisions: 'Paramètres'!$I$32:$I$35
Name Motifs: 'Paramètres'!$J$32:$J$39
Name Actions: 'Paramètres'!$K$32:$K$41
Name OuiNon: 'Paramètres'!$L$32:$L$33
Name Capa: 'Paramètres'!$M$32:$M$35
Name TypesEntretien: 'Paramètres'!$N$32:$N$34
Name StatutsEntretien: 'Paramètres'!$O$32:$O$35
Name AvisEntretien: 'Paramètres'!$P$32:$P$35
Name ZoneBoutons: 'Accueil'!$B$11

Sheet Accueil
A1: GESTION DES CANDIDATURES
A2: Cabinet Victimes & Préjudices — tableau de bord, suivi des candidats, automatisations Outlook et Word
B4: Candidatures | D4: En cours | F4: Entretiens à venir | H4: À traiter | J4: Actions en retard
B5: ='Tableau de bord'!B6 | D5: ='Tableau de bord'!D6 | F5: ='Tableau de bord'!F6 | H5: ='Tableau de bord'!B9 | J5: ='Tableau de bord'!D9
B7: Ces compteurs se mettent à jour automatiquement. Détail complet : onglet « Tableau de bord ».
B9: PILOTAGE — sélectionnez une ligne dans l'onglet Candidatures, puis cliquez | G9: NAVIGATION ET AIDE
B10: Les boutons s'affichent ici après l'installation du module d'automatisation (onglet Notice, 5 minutes). Sans macros, le classeur reste pleinement utilisable à la main.
G11: ▸ Candidatures | H11: Le tableau de suivi : une ligne par candidature.
G12: ▸ Entretiens | H12: Planning et comptes rendus d'entretien.
G13: ▸ Tableau de bord | H13: Statistiques, délais, flux mensuel.
G14: ▸ Journal | H14: Historique automatique des e-mails et documents.
G15: ▸ Modèles e-mails | H15: Textes des messages types, librement modifiables.
G16: ▸ Paramètres | H16: Coordonnées, dossiers, délais, listes déroulantes.
G17: ▸ Notice | H17: Mode d'emploi et installation des automatisations.
G19: AVANT LA PREMIÈRE UTILISATION
G20: 1. Onglet Paramètres : renseignez les coordonnées du cabinet et les chemins des dossiers.
G21: 2. Onglet Paramètres : adaptez les listes (postes, responsables, sources) à votre organisation.
G22: 3. Onglet Modèles e-mails : relisez et ajustez les textes types.
G23: 4. Onglet Notice : installez le module d'automatisation (Outlook / Word).
G24: 5. Onglet Candidatures : supprimez la ligne EXEMPLE-01, puis saisissez vos candidatures.
G26: BON À SAVOIR
G27: • Les colonnes sur fond gris sont calculées : ne rien y saisir.
G28: • La colonne « Alerte » signale les dossiers en retard ou à traiter.
G29: • Pour ajouter une candidature : cliquez sur la première ligne vide sous le tableau.
G30: • Filtrez et triez avec les flèches des en-têtes du tableau.

Sheet Candidatures
A1: SUIVI DES CANDIDATURES
A2: Une ligne = une candidature. Sélectionnez une ligne puis utilisez les boutons ci-dessous (ou l'onglet Accueil). Colonnes grisées = calculées automatiquement, ne rien y saisir.
A3: SUIVI RAPIDE | F3: COORDONNÉES | K3: PROFIL & POSTE | R3: TRAITEMENT DE LA CANDIDATURE | Z3: DÉLAIS (auto) | AB3: DOSSIER & RGPD
A4: ID | B4: Nom | C4: Prénom | D4: Statut | E4: Alerte | F4: Civilité | G4: Date réception | H4: E-mail | I4: Téléphone | J4: Ville | K4: Poste visé | L4: Source | M4: Expérience (ans) | N4: Diplôme / École | O4: CAPA / CRFPA | P4: Disponibilité | Q4: Prétentions (€) | R4: Responsable | S4: Éval. /5 | T4: Date entretien | U4: Décision | V4: Motif (si refus) | W4: Date dernier contact | X4: Prochaine action | Y4: Date prochaine action | Z4: Délai réponse (j) | AA4: Ancienneté (j) | AB4: Dossier candidat | AC4: Consentement vivier | AD4: Purge RGPD le | AE4: Commentaires
A5: EXEMPLE-01 | B5: MARTIN | C5: Camille | D5: 4-Entretien planifié | E5: =IF($A5="","",IF(IFERROR(INDEX(StatutClos,MATCH($D5,StatutListe,0)),"N")="O","Clôturé",IF(AND($Y5<>"",$Y5<Aujourdhui),"Retard",IF($Y5=Aujourdhui,"Aujourd'hui",IF(AND($W5="",$G5<>"",Aujourdhui-$G5>SeuilAccuse),"À traiter","OK"))))) | F5: Mme | G5: 46269 | H5: camille.martin@exemple.fr | I5: 06 12 34 56 78 | J5: Lyon | K5: Avocat collaborateur | L5: Village de la Justice | M5: 3 | N5: M2 Droit du dommage corporel — Lyon III | O5: Oui | P5: 46326 | Q5: 42000 | R5: Associé 1 | S5: 4 | T5: 46286.417 | U5: À statuer | W5: 46271 | X5: Prendre les références | Y5: 46284 | Z5: =IF(OR($A5="",$G5="",$W5=""),"",$W5-$G5) | AA5: =IF(OR($A5="",$G5=""),"",Aujourdhui-$G5) | AB5: C:\Cabinet\Recrutement\Candidats\EXEMPLE-01_MARTIN_Camille | AC5: Oui | AD5: =IF($A5="","",IF($W5<>"",EDATE($W5,12*DureeConservation),IF($G5="","",EDATE($G5,12*DureeConservation)))) | AE5: LIGNE D'EXEMPLE — supprimez-la avant la première utilisation (bouton « Supprimer les exemples » de l'onglet Accueil).
E6: =IF($A6="","",IF(IFERROR(INDEX(StatutClos,MATCH($D6,StatutListe,0)),"N")="O","Clôturé",IF(AND($Y6<>"",$Y6<Aujourdhui),"Retard",IF($Y6=Aujourdhui,"Aujourd'hui",IF(AND($W6="",$G6<>"",Aujourdhui-$G6>SeuilAccuse),"À traiter","OK"))))) | Z6: =IF(OR($A6="",$G6="",$W6=""),"",$W6-$G6) | AA6: =IF(OR($A6="",$G6=""),"",Aujourdhui-$G6) | AD6: =IF($A6="","",IF($W6<>"",EDATE($W6,12*DureeConservation),IF($G6="","",EDATE($G6,12*DureeConservation))))
E7: =IF($A7="","",IF(IFERROR(INDEX(StatutClos,MATCH($D7,StatutListe,0)),"N")="O","Clôturé",IF(AND($Y7<>"",$Y7<Aujourdhui),"Retard",IF($Y7=Aujourdhui,"Aujourd'hui",IF(AND($W7="",$G7<>"",Aujourdhui-$G7>SeuilAccuse),"À traiter","OK"))))) | Z7: =IF(OR($A7="",$G7="",$W7=""),"",$W7-$G7) | AA7: =IF(OR($A7="",$G7=""),"",Aujourdhui-$G7) | AD7: =IF($A7="","",IF($W7<>"",EDATE($W7,12*DureeConservation),IF($G7="","",EDATE($G7,12*DureeConservation))))
E8: =IF($A8="","",IF(IFERROR(INDEX(StatutClos,MATCH($D8,StatutListe,0)),"N")="O","Clôturé",IF(AND($Y8<>"",$Y8<Aujourdhui),"Retard",IF($Y8=Aujourdhui,"Aujourd'hui",IF(AND($W8="",$G8<>"",Aujourdhui-$G8>SeuilAccuse),"À traiter","OK"))))) | Z8: =IF(OR($A8="",$G8="",$W8=""),"",$W8-$G8) | AA8: =IF(OR($A8="",$G8=""),"",Aujourdhui-$G8) | AD8: =IF($A8="","",IF($W8<>"",EDATE($W8,12*DureeConservation),IF($G8="","",EDATE($G8,12*DureeConservation))))
E9: =IF($A9="","",IF(IFERROR(INDEX(StatutClos,MATCH($D9,StatutListe,0)),"N")="O","Clôturé",IF(AND($Y9<>"",$Y9<Aujourdhui),"Retard",IF($Y9=Aujourdhui,"Aujourd'hui",IF(AND($W9="",$G9<>"",Aujourdhui-$G9>SeuilAccuse),"À traiter","OK"))))) | Z9: =IF(OR($A9="",$G9="",$W9=""),"",$W9-$G9) | AA9: =IF(OR($A9="",$G9=""),"",Aujourdhui-$G9) | AD9: =IF($A9="","",IF($W9<>"",EDATE($W9,12*DureeConservation),IF($G9="","",EDATE($G9,12*DureeConservation))))
E10: =IF($A10="","",IF(IFERROR(INDEX(StatutClos,MATCH($D10,StatutListe,0)),"N")="O","Clôturé",IF(AND($Y10<>"",$Y10<Aujourdhui),"Retard",IF($Y10=Aujourdhui,"Aujourd'hui",IF(AND($W10="",$G10<>"",Aujourdhui-$G10>SeuilAccuse),"À traiter","OK"))))) | Z10: =IF(OR($A10="",$G10="",$W10=""),"",$W10-$G10) | AA10: =IF(OR($A10="",$G10=""),"",Aujourdhui-$G10) | AD10: =IF($A10="","",IF($W10<>"",EDATE($W10,12*DureeConservation),IF($G10="","",EDATE($G10,12*DureeConservation))))
E11: =IF($A11="","",IF(IFERROR(INDEX(StatutClos,MATCH($D11,StatutListe,0)),"N")="O","Clôturé",IF(AND($Y11<>"",$Y11<Aujourdhui),"Retard",IF($Y11=Aujourdhui,"Aujourd'hui",IF(AND($W11="",$G11<>"",Aujourdhui-$G11>SeuilAccuse),"À traiter","OK"))))) | Z11: =IF(OR($A11="",$G11="",$W11=""),"",$W11-$G11) | AA11: =IF(OR($A11="",$G11=""),"",Aujourdhui-$G11) | AD11: =IF($A11="","",IF($W11<>"",EDATE($W11,12*DureeConservation),IF($G11="","",EDATE($G11,12*DureeConservation))))
E12: =IF($A12="","",IF(IFERROR(INDEX(StatutClos,MATCH($D12,StatutListe,0)),"N")="O","Clôturé",IF(AND($Y12<>"",$Y12<Aujourdhui),"Retard",IF($Y12=Aujourdhui,"Aujourd'hui",IF(AND($W12="",$G12<>"",Aujourdhui-$G12>SeuilAccuse),"À traiter","OK"))))) | Z12: =IF(OR($A12="",$G12="",$W12=""),"",$W12-$G12) | AA12: =IF(OR($A12="",$G12=""),"",Aujourdhui-$G12) | AD12: =IF($A12="","",IF($W12<>"",EDATE($W12,12*DureeConservation),IF($G12="","",EDATE($G12,12*DureeConservation))))
E13: =IF($A13="","",IF(IFERROR(INDEX(StatutClos,MATCH($D13,StatutListe,0)),"N")="O","Clôturé",IF(AND($Y13<>"",$Y13<Aujourdhui),"Retard",IF($Y13=Aujourdhui,"Aujourd'hui",IF(AND($W13="",$G13<>"",Aujourdhui-$G13>SeuilAccuse),"À traiter","OK"))))) | Z13: =IF(OR($A13="",$G13="",$W13=""),"",$W13-$G13) | AA13: =IF(OR($A13="",$G13=""),"",Aujourdhui-$G13) | AD13: =IF($A13="","",IF($W13<>"",EDATE($W13,12*DureeConservation),IF($G13="","",EDATE($G13,12*DureeConservation))))
E14: =IF($A14="","",IF(IFERROR(INDEX(StatutClos,MATCH($D14,StatutListe,0)),"N")="O","Clôturé",IF(AND($Y14<>"",$Y14<Aujourdhui),"Retard",IF($Y14=Aujourdhui,"Aujourd'hui",IF(AND($W14="",$G14<>"",Aujourdhui-$G14>SeuilAccuse),"À traiter","OK"))))) | Z14: =IF(OR($A14="",$G14="",$W14=""),"",$W14-$G14) | AA14: =IF(OR($A14="",$G14=""),"",Aujourdhui-$G14) | AD14: =IF($A14="","",IF($W14<>"",EDATE($W14,12*DureeConservation),IF($G14="","",EDATE($G14,12*DureeConservation))))
E15: =IF($A15="","",IF(IFERROR(INDEX(StatutClos,MATCH($D15,StatutListe,0)),"N")="O","Clôturé",IF(AND($Y15<>"",$Y15<Aujourdhui),"Retard",IF($Y15=Aujourdhui,"Aujourd'hui",IF(AND($W15="",$G15<>"",Aujourdhui-$G15>SeuilAccuse),"À traiter","OK"))))) | Z15: =IF(OR($A15="",$G15="",$W15=""),"",$W15-$G15) | AA15: =IF(OR($A15="",$G15=""),"",Aujourdhui-$G15) | AD15: =IF($A15="","",IF($W15<>"",EDATE($W15,12*DureeConservation),IF($G15="","",EDATE($G15,12*DureeConservation))))
E16: =IF($A16="","",IF(IFERROR(INDEX(StatutClos,MATCH($D16,StatutListe,0)),"N")="O","Clôturé",IF(AND($Y16<>"",$Y16<Aujourdhui),"Retard",IF($Y16=Aujourdhui,"Aujourd'hui",IF(AND($W16="",$G16<>"",Aujourdhui-$G16>SeuilAccuse),"À traiter","OK"))))) | Z16: =IF(OR($A16="",$G16="",$W16=""),"",$W16-$G16) | AA16: =IF(OR($A16="",$G16=""),"",Aujourdhui-$G16) | AD16: =IF($A16="","",IF($W16<>"",EDATE($W16,12*DureeConservation),IF($G16="","",EDATE($G16,12*DureeConservation))))
E17: =IF($A17="","",IF(IFERROR(INDEX(StatutClos,MATCH($D17,StatutListe,0)),"N")="O","Clôturé",IF(AND($Y17<>"",$Y17<Aujourdhui),"Retard",IF($Y17=Aujourdhui,"Aujourd'hui",IF(AND($W17="",$G17<>"",Aujourdhui-$G17>SeuilAccuse),"À traiter","OK"))))) | Z17: =IF(OR($A17="",$G17="",$W17=""),"",$W17-$G17) | AA17: =IF(OR($A17="",$G17=""),"",Aujourdhui-$G17) | AD17: =IF($A17="","",IF($W17<>"",EDATE($W17,12*DureeConservation),IF($G17="","",EDATE($G17,12*DureeConservation))))
... E34: =IF($A34="","",IF(IFERROR(INDEX(StatutClos,MATCH($D34,StatutListe,0)),"N")="O","Clôturé",IF(AND($Y34<>"",$Y34<Aujourdhui),"Retard",IF($Y34=Aujourdhui,"Aujourd'hui",IF(AND($W34="",$G34<>"",Aujourdhui-$G34>SeuilAccuse),"À traiter","OK"))))) | Z34: =IF(OR($A34="",$G34="",$W34=""),"",$W34-$G34) | AA34: =IF(OR($A34="",$G34=""),"",Aujourdhui-$G34) | AD34: =IF($A34="","",IF($W34<>"",EDATE($W34,12*DureeConservation),IF($G34="","",EDATE($G34,12*DureeConservation))))

Sheet Entretiens
A1: ENTRETIENS
A2: Alimenté automatiquement par le bouton « Planifier un entretien ». Le nom et le poste sont récupérés depuis l'onglet Candidatures à partir de l'ID.
A3: N° entretien | B3: ID candidat | C3: Candidat | D3: Poste visé | E3: Date | F3: Heure | G3: Durée (min) | H3: Type | I3: Lieu / lien visio | J3: Intervenants du cabinet | K3: Statut | L3: Note /20 | M3: Points forts | N3: Points de vigilance | O3: Avis | P3: Compte rendu rédigé
A4: EXEMPLE-E01 | B4: EXEMPLE-01 | C4: =IF($B4="","",IFERROR(INDEX(Candidatures!$B$5:$B$5000,MATCH($B4,Candidatures!$A$5:$A$5000,0))&" "&INDEX(Candidatures!$C$5:$C$5000,MATCH($B4,Candidatures!$A$5:$A$5000,0)),"ID inconnu")) | D4: =IF($B4="","",IFERROR(INDEX(Candidatures!$K$5:$K$5000,MATCH($B4,Candidatures!$A$5:$A$5000,0)),"")) | E4: 46286 | F4: 0.41666667 | G4: 45 | H4: Au cabinet | I4: Salle de réunion — 2e étage | J4: Associé 1, Responsable RH | K4: Planifié | M4: Exemple : maîtrise de la nomenclature Dintilhac.
C5: =IF($B5="","",IFERROR(INDEX(Candidatures!$B$5:$B$5000,MATCH($B5,Candidatures!$A$5:$A$5000,0))&" "&INDEX(Candidatures!$C$5:$C$5000,MATCH($B5,Candidatures!$A$5:$A$5000,0)),"ID inconnu")) | D5: =IF($B5="","",IFERROR(INDEX(Candidatures!$K$5:$K$5000,MATCH($B5,Candidatures!$A$5:$A$5000,0)),""))
C6: =IF($B6="","",IFERROR(INDEX(Candidatures!$B$5:$B$5000,MATCH($B6,Candidatures!$A$5:$A$5000,0))&" "&INDEX(Candidatures!$C$5:$C$5000,MATCH($B6,Candidatures!$A$5:$A$5000,0)),"ID inconnu")) | D6: =IF($B6="","",IFERROR(INDEX(Candidatures!$K$5:$K$5000,MATCH($B6,Candidatures!$A$5:$A$5000,0)),""))
C7: =IF($B7="","",IFERROR(INDEX(Candidatures!$B$5:$B$5000,MATCH($B7,Candidatures!$A$5:$A$5000,0))&" "&INDEX(Candidatures!$C$5:$C$5000,MATCH($B7,Candidatures!$A$5:$A$5000,0)),"ID inconnu")) | D7: =IF($B7="","",IFERROR(INDEX(Candidatures!$K$5:$K$5000,MATCH($B7,Candidatures!$A$5:$A$5000,0)),""))
C8: =IF($B8="","",IFERROR(INDEX(Candidatures!$B$5:$B$5000,MATCH($B8,Candidatures!$A$5:$A$5000,0))&" "&INDEX(Candidatures!$C$5:$C$5000,MATCH($B8,Candidatures!$A$5:$A$5000,0)),"ID inconnu")) | D8: =IF($B8="","",IFERROR(INDEX(Candidatures!$K$5:$K$5000,MATCH($B8,Candidatures!$A$5:$A$5000,0)),""))
C9: =IF($B9="","",IFERROR(INDEX(Candidatures!$B$5:$B$5000,MATCH($B9,Candidatures!$A$5:$A$5000,0))&" "&INDEX(Candidatures!$C$5:$C$5000,MATCH($B9,Candidatures!$A$5:$A$5000,0)),"ID inconnu")) | D9: =IF($B9="","",IFERROR(INDEX(Candidatures!$K$5:$K$5000,MATCH($B9,Candidatures!$A$5:$A$5000,0)),""))
C10: =IF($B10="","",IFERROR(INDEX(Candidatures!$B$5:$B$5000,MATCH($B10,Candidatures!$A$5:$A$5000,0))&" "&INDEX(Candidatures!$C$5:$C$5000,MATCH($B10,Candidatures!$A$5:$A$5000,0)),"ID inconnu")) | D10: =IF($B10="","",IFERROR(INDEX(Candidatures!$K$5:$K$5000,MATCH($B10,Candidatures!$A$5:$A$5000,0)),""))
C11: =IF($B11="","",IFERROR(INDEX(Candidatures!$B$5:$B$5000,MATCH($B11,Candidatures!$A$5:$A$5000,0))&" "&INDEX(Candidatures!$C$5:$C$5000,MATCH($B11,Candidatures!$A$5:$A$5000,0)),"ID inconnu")) | D11: =IF($B11="","",IFERROR(INDEX(Candidatures!$K$5:$K$5000,MATCH($B11,Candidatures!$A$5:$A$5000,0)),""))
C12: =IF($B12="","",IFERROR(INDEX(Candidatures!$B$5:$B$5000,MATCH($B12,Candidatures!$A$5:$A$5000,0))&" "&INDEX(Candidatures!$C$5:$C$5000,MATCH($B12,Candidatures!$A$5:$A$5000,0)),"ID inconnu")) | D12: =IF($B12="","",IFERROR(INDEX(Candidatures!$K$5:$K$5000,MATCH($B12,Candidatures!$A$5:$A$5000,0)),""))
C13: =IF($B13="","",IFERROR(INDEX(Candidatures!$B$5:$B$5000,MATCH($B13,Candidatures!$A$5:$A$5000,0))&" "&INDEX(Candidatures!$C$5:$C$5000,MATCH($B13,Candidatures!$A$5:$A$5000,0)),"ID inconnu")) | D13: =IF($B13="","",IFERROR(INDEX(Candidatures!$K$5:$K$5000,MATCH($B13,Candidatures!$A$5:$A$5000,0)),""))
C14: =IF($B14="","",IFERROR(INDEX(Candidatures!$B$5:$B$5000,MATCH($B14,Candidatures!$A$5:$A$5000,0))&" "&INDEX(Candidatures!$C$5:$C$5000,MATCH($B14,Candidatures!$A$5:$A$5000,0)),"ID inconnu")) | D14: =IF($B14="","",IFERROR(INDEX(Candidatures!$K$5:$K$5000,MATCH($B14,Candidatures!$A$5:$A$5000,0)),""))
C15: =IF($B15="","",IFERROR(INDEX(Candidatures!$B$5:$B$5000,MATCH($B15,Candidatures!$A$5:$A$5000,0))&" "&INDEX(Candidatures!$C$5:$C$5000,MATCH($B15,Candidatures!$A$5:$A$5000,0)),"ID inconnu")) | D15: =IF($B15="","",IFERROR(INDEX(Candidatures!$K$5:$K$5000,MATCH($B15,Candidatures!$A$5:$A$5000,0)),""))
C16: =IF($B16="","",IFERROR(INDEX(Candidatures!$B$5:$B$5000,MATCH($B16,Candidatures!$A$5:$A$5000,0))&" "&INDEX(Candidatures!$C$5:$C$5000,MATCH($B16,Candidatures!$A$5:$A$5000,0)),"ID inconnu")) | D16: =IF($B16="","",IFERROR(INDEX(Candidatures!$K$5:$K$5000,MATCH($B16,Candidatures!$A$5:$A$5000,0)),""))
... C24: =IF($B24="","",IFERROR(INDEX(Candidatures!$B$5:$B$5000,MATCH($B24,Candidatures!$A$5:$A$5000,0))&" "&INDEX(Candidatures!$C$5:$C$5000,MATCH($B24,Candidatures!$A$5:$A$5000,0)),"ID inconnu")) | D24: =IF($B24="","",IFERROR(INDEX(Candidatures!$K$5:$K$5000,MATCH($B24,Candidatures!$A$5:$A$5000,0)),""))

Sheet Tableau de bord
A1: TABLEAU DE BORD DU RECRUTEMENT
A2: Tous les chiffres se recalculent automatiquement à chaque saisie. Aucune manipulation requise.
B4: INDICATEURS CLÉS
B5: Candidatures reçues | D5: Dossiers en cours | F5: Entretiens à venir | H5: Recrutements | J5: Réponses négatives
B6: =COUNTA(Candidatures!$A$5:$A$5000) | D6: =COUNTA(Candidatures!$A$5:$A$5000)-COUNTIF(Candidatures!$D$5:$D$5000,INDEX(StatutListe,8))-COUNTIF(Candidatures!$D$5:$D$5000,INDEX(StatutListe,9))-COUNTIF(Candidatures!$D$5:$D$5000,INDEX(StatutListe,10)) | F6: =COUNTIFS(Candidatures!$T$5:$T$5000,">="&Aujourdhui) | H6: =COUNTIF(Candidatures!$D$5:$D$5000,INDEX(StatutListe,8)) | J6: =COUNTIF(Candidatures!$D$5:$D$5000,INDEX(StatutListe,9))
B8: À traiter | D8: Actions en retard | F8: Délai moyen de réponse | H8: Taux d'entretien | J8: À purger (RGPD)
B9: =COUNTIF(Candidatures!$E$5:$E$5000,"À traiter") | D9: =COUNTIF(Candidatures!$E$5:$E$5000,"Retard") | F9: =IFERROR(AVERAGE(Candidatures!$Z$5:$Z$5000),0) | H9: =IFERROR((COUNTIF(Candidatures!$D$5:$D$5000,INDEX(StatutListe,4))+COUNTIF(Candidatures!$D$5:$D$5000,INDEX(StatutListe,5))+COUNTIF(Candidatures!$D$5:$D$5000,INDEX(StatutListe,7))+COUNTIF(Candidatures!$D$5:$D$5000,INDEX(StatutListe,8)))/COUNTA(Candidatures!$A$5:$A$5000),0) | J9: =COUNTIFS(Candidatures!$AD$5:$AD$5000,">0",Candidatures!$AD$5:$AD$5000,"<="&Aujourdhui)
B12: RÉPARTITION PAR STATUT | G12: RÉPARTITION PAR POSTE
B13: Libellé | C13: Nb | D13: Part | G13: Libellé | H13: Nb | I13: Part
B14: =INDEX(StatutListe,1) | C14: =COUNTIF(Candidatures!$D$5:$D$5000,$B14) | D14: =IFERROR(C14/COUNTA(Candidatures!$A$5:$A$5000),0) | E14: =C14 | G14: =INDEX(Postes,1) | H14: =COUNTIF(Candidatures!$K$5:$K$5000,$G14) | I14: =IFERROR(H14/COUNTA(Candidatures!$A$5:$A$5000),0) | J14: =H14
B15: =INDEX(StatutListe,2) | C15: =COUNTIF(Candidatures!$D$5:$D$5000,$B15) | D15: =IFERROR(C15/COUNTA(Candidatures!$A$5:$A$5000),0) | E15: =C15 | G15: =INDEX(Postes,2) | H15: =COUNTIF(Candidatures!$K$5:$K$5000,$G15) | I15: =IFERROR(H15/COUNTA(Candidatures!$A$5:$A$5000),0) | J15: =H15
B16: =INDEX(StatutListe,3) | C16: =COUNTIF(Candidatures!$D$5:$D$5000,$B16) | D16: =IFERROR(C16/COUNTA(Candidatures!$A$5:$A$5000),0) | E16: =C16 | G16: =INDEX(Postes,3) | H16: =COUNTIF(Candidatures!$K$5:$K$5000,$G16) | I16: =IFERROR(H16/COUNTA(Candidatures!$A$5:$A$5000),0) | J16: =H16
B17: =INDEX(StatutListe,4) | C17: =COUNTIF(Candidatures!$D$5:$D$5000,$B17) | D17: =IFERROR(C17/COUNTA(Candidatures!$A$5:$A$5000),0) | E17: =C17 | G17: =INDEX(Postes,4) | H17: =COUNTIF(Candidatures!$K$5:$K$5000,$G17) | I17: =IFERROR(H17/COUNTA(Candidatures!$A$5:$A$5000),0) | J17: =H17
B18: =INDEX(StatutListe,5) | C18: =COUNTIF(Candidatures!$D$5:$D$5000,$B18) | D18: =IFERROR(C18/COUNTA(Candidatures!$A$5:$A$5000),0) | E18: =C18 | G18: =INDEX(Postes,5) | H18: =COUNTIF(Candidatures!$K$5:$K$5000,$G18) | I18: =IFERROR(H18/COUNTA(Candidatures!$A$5:$A$5000),0) | J18: =H18
B19: =INDEX(StatutListe,6) | C19: =COUNTIF(Candidatures!$D$5:$D$5000,$B19) | D19: =IFERROR(C19/COUNTA(Candidatures!$A$5:$A$5000),0) | E19: =C19 | G19: =INDEX(Postes,6) | H19: =COUNTIF(Candidatures!$K$5:$K$5000,$G19) | I19: =IFERROR(H19/COUNTA(Candidatures!$A$5:$A$5000),0) | J19: =H19
B20: =INDEX(StatutListe,7) | C20: =COUNTIF(Candidatures!$D$5:$D$5000,$B20) | D20: =IFERROR(C20/COUNTA(Candidatures!$A$5:$A$5000),0) | E20: =C20 | G20: =INDEX(Postes,7) | H20: =COUNTIF(Candidatures!$K$5:$K$5000,$G20) | I20: =IFERROR(H20/COUNTA(Candidatures!$A$5:$A$5000),0) | J20: =H20
B21: =INDEX(StatutListe,8) | C21: =COUNTIF(Candidatures!$D$5:$D$5000,$B21) | D21: =IFERROR(C21/COUNTA(Candidatures!$A$5:$A$5000),0) | E21: =C21 | G21: =INDEX(Postes,8) | H21: =COUNTIF(Candidatures!$K$5:$K$5000,$G21) | I21: =IFERROR(H21/COUNTA(Candidatures!$A$5:$A$5000),0) | J21: =H21
B22: =INDEX(StatutListe,9) | C22: =COUNTIF(Candidatures!$D$5:$D$5000,$B22) | D22: =IFERROR(C22/COUNTA(Candidatures!$A$5:$A$5000),0) | E22: =C22 | G22: =INDEX(Postes,9) | H22: =COUNTIF(Candidatures!$K$5:$K$5000,$G22) | I22: =IFERROR(H22/COUNTA(Candidatures!$A$5:$A$5000),0) | J22: =H22
B23: =INDEX(StatutListe,10) | C23: =COUNTIF(Candidatures!$D$5:$D$5000,$B23) | D23: =IFERROR(C23/COUNTA(Candidatures!$A$5:$A$5000),0) | E23: =C23 | G23: =INDEX(Postes,10) | H23: =COUNTIF(Candidatures!$K$5:$K$5000,$G23) | I23: =IFERROR(H23/COUNTA(Candidatures!$A$5:$A$5000),0) | J23: =H23
B25: RÉPARTITION PAR SOURCE | G25: RÉPARTITION PAR RESPONSABLE
B26: Libellé | C26: Nb | D26: Part | G26: Libellé | H26: Nb | I26: Part
B27: =INDEX(Sources,1) | C27: =COUNTIF(Candidatures!$L$5:$L$5000,$B27) | D27: =IFERROR(C27/COUNTA(Candidatures!$A$5:$A$5000),0) | E27: =C27 | G27: =INDEX(Responsables,1) | H27: =COUNTIF(Candidatures!$R$5:$R$5000,$G27) | I27: =IFERROR(H27/COUNTA(Candidatures!$A$5:$A$5000),0) | J27: =H27
B28: =INDEX(Sources,2) | C28: =COUNTIF(Candidatures!$L$5:$L$5000,$B28) | D28: =IFERROR(C28/COUNTA(Candidatures!$A$5:$A$5000),0) | E28: =C28 | G28: =INDEX(Responsables,2) | H28: =COUNTIF(Candidatures!$R$5:$R$5000,$G28) | I28: =IFERROR(H28/COUNTA(Candidatures!$A$5:$A$5000),0) | J28: =H28
B29: =INDEX(Sources,3) | C29: =COUNTIF(Candidatures!$L$5:$L$5000,$B29) | D29: =IFERROR(C29/COUNTA(Candidatures!$A$5:$A$5000),0) | E29: =C29 | G29: =INDEX(Responsables,3) | H29: =COUNTIF(Candidatures!$R$5:$R$5000,$G29) | I29: =IFERROR(H29/COUNTA(Candidatures!$A$5:$A$5000),0) | J29: =H29
B30: =INDEX(Sources,4) | C30: =COUNTIF(Candidatures!$L$5:$L$5000,$B30) | D30: =IFERROR(C30/COUNTA(Candidatures!$A$5:$A$5000),0) | E30: =C30 | G30: =INDEX(Responsables,4) | H30: =COUNTIF(Candidatures!$R$5:$R$5000,$G30) | I30: =IFERROR(H30/COUNTA(Candidatures!$A$5:$A$5000),0) | J30: =H30
B31: =INDEX(Sources,5) | C31: =COUNTIF(Candidatures!$L$5:$L$5000,$B31) | D31: =IFERROR(C31/COUNTA(Candidatures!$A$5:$A$5000),0) | E31: =C31 | G31: =INDEX(Responsables,5) | H31: =COUNTIF(Candidatures!$R$5:$R$5000,$G31) | I31: =IFERROR(H31/COUNTA(Candidatures!$A$5:$A$5000),0) | J31: =H31
B32: =INDEX(Sources,6) | C32: =COUNTIF(Candidatures!$L$5:$L$5000,$B32) | D32: =IFERROR(C32/COUNTA(Candidatures!$A$5:$A$5000),0) | E32: =C32 | G32: =INDEX(Responsables,6) | H32: =COUNTIF(Candidatures!$R$5:$R$5000,$G32) | I32: =IFERROR(H32/COUNTA(Candidatures!$A$5:$A$5000),0) | J32: =H32
B33: =INDEX(Sources,7) | C33: =COUNTIF(Candidatures!$L$5:$L$5000,$B33) | D33: =IFERROR(C33/COUNTA(Candidatures!$A$5:$A$5000),0) | E33: =C33
B34: =INDEX(Sources,8) | C34: =COUNTIF(Candidatures!$L$5:$L$5000,$B34) | D34: =IFERROR(C34/COUNTA(Candidatures!$A$5:$A$5000),0) | E34: =C34
B35: =INDEX(Sources,9) | C35: =COUNTIF(Candidatures!$L$5:$L$5000,$B35) | D35: =IFERROR(C35/COUNTA(Candidatures!$A$5:$A$5000),0) | E35: =C35
B36: =INDEX(Sources,10) | C36: =COUNTIF(Candidatures!$L$5:$L$5000,$B36) | D36: =IFERROR(C36/COUNTA(Candidatures!$A$5:$A$5000),0) | E36: =C36
B38: FLUX DES CANDIDATURES — 12 DERNIERS MOIS
B39: =EDATE(DATE(YEAR(Aujourdhui),MONTH(Aujourdhui),1),-11) | C39: =COUNTIFS(Candidatures!$G$5:$G$5000,">="&$B39,Candidatures!$G$5:$G$5000,"<"&EDATE($B39,1)) | D39: =$C39
B40: =EDATE(DATE(YEAR(Aujourdhui),MONTH(Aujourdhui),1),-10) | C40: =COUNTIFS(Candidatures!$G$5:$G$5000,">="&$B40,Candidatures!$G$5:$G$5000,"<"&EDATE($B40,1)) | D40: =$C40
B41: =EDATE(DATE(YEAR(Aujourdhui),MONTH(Aujourdhui),1),-9) | C41: =COUNTIFS(Candidatures!$G$5:$G$5000,">="&$B41,Candidatures!$G$5:$G$5000,"<"&EDATE($B41,1)) | D41: =$C41
B42: =EDATE(DATE(YEAR(Aujourdhui),MONTH(Aujourdhui),1),-8) | C42: =COUNTIFS(Candidatures!$G$5:$G$5000,">="&$B42,Candidatures!$G$5:$G$5000,"<"&EDATE($B42,1)) | D42: =$C42
B43: =EDATE(DATE(YEAR(Aujourdhui),MONTH(Aujourdhui),1),-7) | C43: =COUNTIFS(Candidatures!$G$5:$G$5000,">="&$B43,Candidatures!$G$5:$G$5000,"<"&EDATE($B43,1)) | D43: =$C43
B44: =EDATE(DATE(YEAR(Aujourdhui),MONTH(Aujourdhui),1),-6) | C44: =COUNTIFS(Candidatures!$G$5:$G$5000,">="&$B44,Candidatures!$G$5:$G$5000,"<"&EDATE($B44,1)) | D44: =$C44
B45: =EDATE(DATE(YEAR(Aujourdhui),MONTH(Aujourdhui),1),-5) | C45: =COUNTIFS(Candidatures!$G$5:$G$5000,">="&$B45,Candidatures!$G$5:$G$5000,"<"&EDATE($B45,1)) | D45: =$C45
B46: =EDATE(DATE(YEAR(Aujourdhui),MONTH(Aujourdhui),1),-4) | C46: =COUNTIFS(Candidatures!$G$5:$G$5000,">="&$B46,Candidatures!$G$5:$G$5000,"<"&EDATE($B46,1)) | D46: =$C46
...

Sheet Journal
A1: JOURNAL DES ACTIONS
A2: Rempli automatiquement par les macros (e-mails envoyés, documents générés, imports). Sert de preuve de traitement et de traçabilité RGPD. Ne pas saisir manuellement.
A3: Horodatage | B3: Utilisateur | C3: ID candidat | D3: Candidat | E3: Action | F3: Détail | G3: Résultat
A4: 46281.292 | B4: Exemple | C4: EXEMPLE-01 | D4: MARTIN Camille | E4: Accusé de réception | F4: E-mail envoyé à camille.martin@exemple.fr | G4: OK

Sheet Modèles e-mails
A1: MODÈLES D'E-MAILS
A2: Textes envoyés par les boutons d'automatisation. Modifiez-les librement : ne touchez pas à la colonne « Clé », utilisée par les macros.
A3: Clé | B3: Libellé du bouton | C3: Objet de l'e-mail | D3: Corps du message | E3: Pièce jointe (chemin complet)
A4: ACCUSE_RECEPTION | B4: Accusé de réception | C4: Votre candidature au poste de {{POSTE}} — {{CABINET}} | D4: {{CIVILITE_LONGUE}}, Nous accusons réception de votre candidature au poste de {{POSTE}}, qui nous est parvenue le {{DATE_RECEPTION}}, et vous remercions de l'intérêt que vous portez à notre cabinet. Votre dossier est en cours d'examen par {{RESPONSABLE}}. Nous reviendrons vers vous dans un délai de trois semaines, que la suite donnée soit favorable ou non. Nous vous prions d'agréer, {{CIVILITE_LONGUE}}, l'expression de nos salutations distinguées. Conformément au règlement (UE) 2016/679, les données de votre candidature sont conservées {{DUREE_CONSERVATION}} ans à compter de notre dernier échange, aux seules fins du recrutement. Vous pouvez exercer vos droits d'accès, de rectification et d'effacement à l'adresse {{EMAIL_RH}}. {{SIGNATURE_BLOC}}
A5: DEMANDE_PIECES | B5: Demande de pièces complémentaires | C5: Votre candidature — pièces complémentaires | D5: {{CIVILITE_LONGUE}}, Nous avons bien reçu votre candidature au poste de {{POSTE}}. Afin de poursuivre son examen, nous vous remercions de nous transmettre les éléments suivants : • votre curriculum vitae actualisé ; • une lettre de motivation ; • le cas échéant, une copie de votre CAPA ou de votre attestation de réussite ; • vos dates de disponibilité. Ces pièces peuvent être adressées en réponse au présent message. Nous vous prions d'agréer, {{CIVILITE_LONGUE}}, l'expression de nos salutations distinguées. {{SIGNATURE_BLOC}}
A6: CONVOCATION | B6: Convocation à un entretien | C6: Entretien — poste de {{POSTE}} — {{CABINET}} | D6: {{CIVILITE_LONGUE}}, Votre candidature au poste de {{POSTE}} a retenu notre attention. Nous vous proposons de nous rencontrer le {{DATE_ENTRETIEN}} à {{HEURE_ENTRETIEN}}. Modalité : {{TYPE_ENTRETIEN}} Lieu / lien : {{LIEU_ENTRETIEN}} Durée prévue : environ {{DUREE_ENTRETIEN}} minutes Vous serez reçu(e) par {{RESPONSABLE}}. Nous vous remercions de bien vouloir confirmer votre présence en réponse à ce message. Si ce créneau ne vous convenait pas, n'hésitez pas à nous proposer d'autres disponibilités. Nous vous prions d'agréer, {{CIVILITE_LONGUE}}, l'expression de nos salutations distinguées. {{SIGNATURE_BLOC}}
A7: RELANCE_CANDIDAT | B7: Relance du candidat | C7: Votre candidature au poste de {{POSTE}} — relance | D7: {{CIVILITE_LONGUE}}, Sauf erreur de notre part, notre message du {{DATE_DERNIER_CONTACT}} relatif à votre candidature au poste de {{POSTE}} est resté sans réponse. Nous restons à votre disposition et vous remercions de nous indiquer si vous souhaitez maintenir votre candidature. Nous vous prions d'agréer, {{CIVILITE_LONGUE}}, l'expression de nos salutations distinguées. {{SIGNATURE_BLOC}}
A8: VIVIER | B8: Mise en vivier | C8: Votre candidature — {{CABINET}} | D8: {{CIVILITE_LONGUE}}, Nous avons étudié avec attention votre candidature au poste de {{POSTE}}. Si nous ne sommes pas en mesure d'y donner une suite favorable dans l'immédiat, votre profil a retenu notre intérêt. Sous réserve de votre accord, nous conserverons votre dossier afin de vous recontacter dès qu'un poste correspondant se libérera. Il vous suffit de nous répondre par la négative pour que votre dossier soit supprimé sans délai. Nous vous prions d'agréer, {{CIVILITE_LONGUE}}, l'expression de nos salutations distinguées. Conformément au règlement (UE) 2016/679, les données de votre candidature sont conservées {{DUREE_CONSERVATION}} ans à compter de notre dernier échange, aux seules fins du recrutement. Vous pouvez exercer vos droits d'accès, de rectification et d'effacement à l'adresse {{EMAIL_RH}}. {{SIGNATURE_BLOC}}
A9: REFUS | B9: Réponse négative | C9: Votre candidature au poste de {{POSTE}} — {{CABINET}} | D9: {{CIVILITE_LONGUE}}, Nous avons étudié avec attention votre candidature au poste de {{POSTE}} et vous remercions de la confiance que vous avez témoignée à notre cabinet. Nous sommes au regret de ne pouvoir y donner une suite favorable. Cette décision ne remet nullement en cause la qualité de votre parcours ; elle tient à l'adéquation entre votre profil et les besoins actuels du cabinet. Nous vous souhaitons une pleine réussite dans la suite de votre parcours professionnel et vous prions d'agréer, {{CIVILITE_LONGUE}}, l'expression de nos salutations distinguées. Conformément au règlement (UE) 2016/679, les données de votre candidature sont conservées {{DUREE_CONSERVATION}} ans à compter de notre dernier échange, aux seules fins du recrutement. Vous pouvez exercer vos droits d'accès, de rectification et d'effacement à l'adresse {{EMAIL_RH}}. {{SIGNATURE_BLOC}}
A10: PROPOSITION | B10: Proposition / suite favorable | C10: Votre candidature au poste de {{POSTE}} — suite favorable | D10: {{CIVILITE_LONGUE}}, À l'issue de nos échanges, nous avons le plaisir de vous confirmer notre souhait de vous accueillir au sein du cabinet au poste de {{POSTE}}. Vous trouverez ci-joint le document reprenant les conditions envisagées. Nous vous remercions de nous faire part de vos observations et de votre date de disponibilité. Nous restons à votre entière disposition et vous prions d'agréer, {{CIVILITE_LONGUE}}, l'expression de nos salutations distinguées. {{SIGNATURE_BLOC}}
A12: BALISES DISPONIBLES — remplacées automatiquement à l'envoi
A13: {{CIVILITE}} | B13: M. / Mme — pour le bloc adresse
A14: {{CIVILITE_LONGUE}} | B14: Madame / Monsieur — pour l'appel et la formule de politesse
A15: {{NOM}} | B15: Nom du candidat
A16: {{PRENOM}} | B16: Prénom
A17: {{POSTE}} | B17: Poste visé
A18: {{ID}} | B18: Identifiant de la candidature
A19: {{DATE_RECEPTION}} | B19: Date de réception de la candidature
A20: {{DATE_DERNIER_CONTACT}} | B20: Date du dernier contact
A21: {{DATE_ENTRETIEN}} | B21: Date de l'entretien (jj/mm/aaaa)
A22: {{HEURE_ENTRETIEN}} | B22: Heure de l'entretien
A23: {{DUREE_ENTRETIEN}} | B23: Durée en minutes
A24: {{TYPE_ENTRETIEN}} | B24: Au cabinet / visio / téléphone
... A35: {{DUREE_CONSERVATION}} | B35: Durée de conservation RGPD, en années

Sheet Paramètres
A1: PARAMÈTRES DU CABINET
A2: Toutes les cellules sur fond crème sont à personnaliser. Les listes ci-dessous alimentent les menus déroulants de l'onglet Candidatures.
B4: IDENTITÉ DU CABINET
B5: Nom du cabinet | C5: Cabinet Victimes & Préjudices
B6: Adresse (1 ligne) | C6: — à compléter —
B7: Téléphone | C7: — à compléter —
B8: E-mail recrutement | C8: recrutement@victimesetprejudices.fr | E8: Adresse affichée dans les courriers et les modèles d'e-mails.
B9: Site internet | C9: https://www.victimesetprejudices.fr
B10: Signataire des courriers | C10: — à compléter —
B11: Fonction du signataire | C11: Avocat associé
B12: Signature e-mail | C12: Cordialement, | E12: Laissez vide pour conserver la signature Outlook par défaut (recommandé).
B13: Ville (lieu de signature) | C13: — à compléter — | E13: Figure en tête des courriers : « Lyon, le 15/09/2026 ».
B15: AUTOMATISATIONS (Outlook / Word)
B16: Mode d'envoi des e-mails | C16: Afficher avant envoi | E16: « Afficher avant envoi » (recommandé) ou « Envoyer directement ».
B17: Dossier des candidats | C17: C:\Cabinet\Recrutement\Candidats | E17: Un sous-dossier par candidat y est créé automatiquement (CV, LM, pièces).
B18: Dossier des modèles Word | C18: C:\Cabinet\Recrutement\Modeles | E18: Déposez-y les fichiers .docx fournis avec ce classeur.
B19: Dossier Outlook à importer | C19: Candidatures | E19: Nom du dossier de la boîte de réception scanné par « Importer depuis Outlook ».
B20: Générer aussi un PDF | C20: Oui | E20: Chaque document Word produit est également enregistré en PDF.
B22: DÉLAIS ET CONFORMITÉ
B23: Délai d'accusé de réception (jours) | C23: 7 | E23: Hypothèse cabinet, modifiable : au-delà, la candidature passe en « À traiter ».
B24: Délai de relance (jours) | C24: 21 | E24: Hypothèse cabinet, modifiable : utilisé par le bouton « Relances ».
B25: Conservation des données (années) | C25: 2 | E25: Recommandation CNIL : 2 ans à compter du dernier contact avec le candidat.
B26: Date du jour (automatique) | C26: =TODAY() | E26: Cellule calculée — ne pas modifier. Sert à tous les indicateurs de délai.
B29: LISTES DÉROULANTES — ajoutez ou renommez librement les valeurs
B30: Après ajout d'une valeur en fin de liste, cliquez sur « Actualiser les listes » (onglet Accueil) pour étendre le menu déroulant correspondant.
B31: Civilité | C31: Postes | D31: Sources | E31: Statuts | F31: Clôturé ? | G31: Responsables | H31: Évaluation | I31: Décisions | J31: Motifs de refus | K31: Prochaines actions | L31: Oui / Non | M31: CAPA / CRFPA | N31: Type d'entretien | O31: Statut entretien | P31: Avis entretien
B32: M. | C32: Avocat collaborateur | D32: Candidature spontanée | E32: 1-Reçue | F32: N | G32: — à compléter — | H32: 1 | I32: À statuer | J32: Profil non adapté au poste | K32: Accuser réception | L32: Oui | M32: Oui | N32: Au cabinet | O32: Planifié | P32: Très favorable
B33: Mme | C33: Élève-avocat (stage PPI) | D33: Site du cabinet | E33: 2-Accusé de réception | F33: N | G33: Associé 1 | H33: 2 | I33: Favorable | J33: Expérience insuffisante | K33: Étudier le dossier | L33: Non | M33: Non | N33: Visioconférence | O33: Réalisé | P33: Favorable
C34: Juriste dommage corporel | D34: LinkedIn | E34: 3-En cours d'examen | F34: N | G34: Associé 2 | H34: 3 | I34: Vivier | J34: Spécialité différente | K34: Demander pièces manquantes | M34: En cours | N34: Téléphone | O34: Annulé | P34: Réservé
C35: Stagiaire M1 / M2 | D35: Village de la Justice | E35: 4-Entretien planifié | F35: N | G35: Responsable RH | H35: 4 | I35: Défavorable | J35: Prétentions salariales | K35: Planifier un entretien | M35: Non concerné | O35: Reporté | P35: Défavorable
C36: Assistant(e) juridique | D36: Indeed | E36: 5-Entretien réalisé | F36: N | G36: Secrétariat | H36: 5 | J36: Poste déjà pourvu | K36: Second entretien
C37: Secrétaire juridique | D37: École / Université | E37: 6-Vivier | F37: N | G37: Non attribué | J37: Pas de disponibilité compatible | K37: Prendre les références
C38: Alternant(e) | D38: Cooptation | E38: 7-Proposition envoyée | F38: N | J38: Sans suite du candidat | K38: Envoyer une proposition
C39: Chargé(e) de recouvrement | D39: Barreau / CNB | E39: 8-Recruté(e) | F39: O | J39: Autre | K39: Envoyer un refus
C40: Stage découverte | D40: Pôle emploi | E40: 9-Refusée | F40: O | K40: Relancer le candidat
C41: Autre | D41: Autre | E41: 10-Désistement | F41: O | K41: Classer en vivier

Sheet Notice
A1: MODE D'EMPLOI
A2: Prise en main, installation des automatisations Outlook et Word, dépannage
B5: 1. À QUOI SERT CHAQUE ONGLET
B6: Accueil | C6: Compteurs du jour, boutons d'automatisation, liens vers les autres onglets.
B7: Candidatures | C7: Le cœur de l'outil : une ligne par candidature reçue, de la réception à la décision.
B8: Entretiens | C8: Un entretien par ligne : date, intervenants, note, avis. Rempli par le bouton de planification.
B9: Tableau de bord | C9: Statistiques automatiques : statuts, postes, sources, responsables, délais, flux mensuel.
B10: Journal | C10: Trace horodatée de chaque e-mail envoyé et de chaque document généré.
B11: Modèles e-mails | C11: Les textes envoyés par les boutons. Modifiables librement, sauf la colonne « Clé ».
B12: Paramètres | C12: Coordonnées du cabinet, dossiers de travail, délais, et toutes les listes déroulantes.
B13: Notice | C13: Le présent mode d'emploi.
B15: 2. PRISE EN MAIN EN CINQ MINUTES
B16: Étape 1 | C16: Onglet Paramètres : complétez les cellules sur fond crème (adresse, téléphone, e-mail de recrutement, signataire).
B17: Étape 2 | C17: Toujours dans Paramètres : indiquez les trois dossiers de travail (candidats, modèles Word, dossier Outlook).
B18: Étape 3 | C18: Adaptez les listes déroulantes à votre organisation : postes ouverts, responsables, sources de candidature.
B19: Étape 4 | C19: Onglet Candidatures : supprimez la ligne EXEMPLE-01, puis saisissez votre première candidature.
B20: Étape 5 | C20: Installez le module d'automatisation (section 3) pour activer les boutons Outlook et Word.
B21: ℹ Le classeur fonctionne parfaitement sans macros : vous perdez seulement l'envoi automatique des e-mails et la génération des documents Word.
B23: 3. ACTIVER LES AUTOMATISATIONS OUTLOOK ET WORD
B24: ℹ À faire une seule fois, sur chaque poste qui utilisera les boutons. Durée : environ 5 minutes.
B25: 1. Enregistrer au bon format | C25: Fichier ▸ Enregistrer sous ▸ type « Classeur Excel prenant en charge les macros (*.xlsm) ». Indispensable : un fichier .xlsx ne peut pas contenir de macros.
B26: 2. Débloquer le fichier | C26: Fermez Excel. Dans l'Explorateur, clic droit sur le fichier ▸ Propriétés ▸ cochez « Débloquer » ▸ OK. Windows bloque par défaut les macros des fichiers reçus par e-mail ou téléchargés.
B27: 3. Ouvrir l'éditeur de macros | C27: Rouvrez le classeur, puis appuyez sur Alt + F11.
B28: 4. Importer le module | C28: Dans l'éditeur : menu Fichier ▸ Importer un fichier… (raccourci Ctrl + M) ▸ sélectionnez VP_Candidatures.bas ▸ Ouvrir. Un élément « VP_Candidatures » apparaît sous Modules, à gauche, dans l'arborescence du classeur.
B29: 4 bis. Si l'import échoue | C29: Utilisez la variante copier-coller, qui fonctionne dans tous les cas : dans l'éditeur, menu Insertion ▸ Module ; ouvrez VP_Candidatures_a_coller.txt avec le Bloc-notes ; Ctrl + A puis Ctrl + C ; revenez dans la fenêtre blanche de l'éditeur et faites Ctrl + V.
B30: 5. Lancer l'installation | C30: Revenez dans Excel (Alt + F11) puis appuyez sur Alt + F8 : choisissez « Installer » dans la liste des macros et cliquez sur Exécuter. Les boutons apparaissent alors dans l'onglet Accueil et en haut de l'onglet Candidatures.
B31: ℹ Variante depuis l'éditeur : cliquez dans le corps de la procédure Installer, puis appuyez sur F5. Le libellé du menu Exécution varie selon les versions — « Exécuter la macro » ou « Exécuter Sub/UserForm » — mais il s'agit de la même commande, et c'est la position du curseur qui détermine la procédure lancée.
B32: 6. Enregistrer | C32: Revenez dans Excel (Alt + F11) et enregistrez. C'est terminé.
B33: ℹ Si un bandeau jaune « Avertissement de sécurité » s'affiche à l'ouverture, cliquez sur « Activer le contenu ». Le classeur est alors considéré comme approuvé sur ce poste.
B34: ℹ Aucune référence VBA supplémentaire n'est nécessaire : le module dialogue avec Outlook et Word en liaison tardive.
B36: 4. CE QUE FAIT CHAQUE BOUTON
B37: Nouvelle candidature | C37: Ajoute une ligne, attribue l'identifiant (CAND-année-numéro) et la date du jour.
B38: Importer depuis Outlook | C38: Parcourt le dossier Outlook indiqué dans Paramètres, crée une ligne par message non lu, enregistre les pièces jointes dans le dossier du candidat et marque le message comme lu.
B39: Accusé de réception | C39: Prépare l'e-mail d'accusé de réception, passe le statut à « 2-Accusé de réception » et met à jour la date de dernier contact.
B40: Demander des pièces | C40: Envoie la demande de pièces complémentaires et programme une relance.
B41: Planifier un entretien | C41: Demande la date, l'heure et les modalités ; crée le rendez-vous Outlook avec invitation au candidat, ajoute la ligne dans l'onglet Entretiens et envoie la convocation.
B42: Mettre en vivier | C42: Envoie le message de mise en vivier et bascule le statut correspondant.
B43: Réponse négative | C43: Envoie la réponse négative après confirmation, enregistre le motif et clôture le dossier.
B44: Proposition / suite favorable | C44: Envoie le message de suite favorable et passe le statut à « 7-Proposition envoyée ».
B45: Envoi groupé | C45: Applique le même modèle d'e-mail à toutes les lignes sélectionnées (utile quand un poste est pourvu).
...
